Workbook
Name Administracion: Listados!$C$2:$C$15
Name Almacen_PC: Listados!#REF!
Name Almacen_PC: Listados!#REF!
Name Almacen_PC: Listados!#REF!
Name Almacen_PC: Listados!#REF!
Name Almacen_PC: Listados!#REF!
Name Almacen_PC: Listados!#REF!
Name Almacen_PC: Listados!#REF!
Name Almacen_PC: Listados!#REF!
Name Almacen_PC: Listados!#REF!
Name Almacen_PC: Listados!#REF!
Name Almacen_PC: Listados!#REF!
Name Almacen_PC: Listados!#REF!
Name Almacen_PC: Listados!#REF!
Name Almacen_PC: Listados!#REF!
Name Almacen_PC: Listados!#REF!
Name Contenedores: Listados!$B$2:$B$15
Name Gasolinera: Listados!$L$2:$L$15
Name Interchange: Listados!$G$2:$G$15
Name Interchange_PC: Listados!$G$2:$G$15
Name Interchange_SL: Listados!$H$2:$H$15
Name Predio_Puerto_Cortes: Listados!$E$2:$E$15
Name Predio_San_Lorenzo: Listados!$F$2:$F$15
Name Servicio_Al_Cliente: Listados!$D$2:$D$15
Name ServicioAlCliente: Listados!$D$2:$D$15
Name Sistemas_Y_Procesos: Listados!$A$2:$A$15
Name SistemasYProcesos: Listados!$A$2:$A$15
Name SLO: Listados!#REF!
Name SLO: Listados!#REF!
Name SLO: Listados!#REF!
Name SLO: Listados!#REF!
Name SLO: Listados!#REF!
Name SLO: Listados!#REF!
Name SLO: Listados!#REF!
Name SLO: Listados!#REF!
Name SLO: Listados!#REF!
Name SLO: Listados!#REF!
Name SLO: Listados!#REF!
Name SLO: Listados!#REF!
Name Taller: Listados!#REF!
Name Taller: Listados!#REF!
Name Taller: Listados!#REF!
Name Taller: Listados!#REF!
Name Taller: Listados!#REF!
Name Taller: Listados!#REF!
Name Taller: Listados!#REF!
Name Taller: Listados!#REF!
Name Taller: Listados!#REF!
Name Taller: Listados!#REF!
Name Taller: Listados!#REF!
Name Taller: Listados!#REF!
Name Taller: Listados!#REF!
Name Taller: Listados!#REF!
Name Taller: Listados!#REF!
Name Taller_PC: Listados!$I$2:$I$15
Name Taller_SL: Listados!$J$2:$J$15
Name Transporte: Listados!$K$2:$K$15

Sheet Contenedores
I1: 0.9
C2: Colaborador: | I2: 80-90%
C3: Departamento: | D3: Contenedores | I3: Menos de 80%
A5: =+Mensual!B5 -> No | B5: =+Mensual!C5 -> Peso | D5: =+Mensual!E5 -> Unidad de medición | E5: =+Mensual!F5 -> Meta | F5: =+Mensual!G5 -> Resultado | G5: =+Mensual!H5 -> Nota | H5: =+Mensual!I5 -> Valor ponderado | I5: =+Mensual!J5 -> 0 | J5: =+Mensual!K5 -> 0.25 | K5: =+Mensual!L5 -> 0.5 | ... Q5: =+Mensual!R5 -> 0 | T5: Nota | U5: Nota
A6: =+Mensual!B6 -> 4 | B6: 0.3 | C6: 1.2 Lograr meta de contenedores | D6: =IF(VLOOKUP($C6,Mensual!$D$6:$G$163,2,0)<0,0,VLOOKUP($C6,Mensual!$D$6:$G$163,2,0)) -> 0 | E6: =IF(VLOOKUP($C6,Mensual!$D$6:$G$163,3,0)<0,0,VLOOKUP($C6,Mensual!$D$6:$G$163,3,0)) -> 15 | F6: =IF(VLOOKUP($C6,Mensual!$D$6:$G$163,4,0)<0,0,VLOOKUP($C6,Mensual!$D$6:$G$163,4,0)) -> 1 | G6: =IF(VLOOKUP($C6,Mensual!$D$6:$H$163,5,0)<0,0,VLOOKUP($C6,Mensual!$D$6:$H$163,5,0)) -> 0.066666667 | H6: =+G6*B6 -> 0.02 | I6: =+Mensual!J6 -> 0 | J6: =+Mensual!K6 -> 0 | K6: =+Mensual!L6 -> 0 | L6: =+Mensual!M6 -> 0
B7: 0.1 | C7: 9. SCORE CARD Grupo EXA | D7: =IF(VLOOKUP($C7,Mensual!$D$6:$G$163,2,0)<0,0,VLOOKUP($C7,Mensual!$D$6:$G$163,2,0)) -> RESULTADO SCORECARD | E7: =IF(VLOOKUP($C7,Mensual!$D$6:$G$163,3,0)<0,0,VLOOKUP($C7,Mensual!$D$6:$G$163,3,0)) -> 1 | F7: =IF(VLOOKUP($C7,Mensual!$D$6:$G$163,4,0)<0,0,VLOOKUP($C7,Mensual!$D$6:$G$163,4,0)) -> 1.0325 | G7: =IF(VLOOKUP($C7,Mensual!$D$6:$H$163,5,0)<0,0,VLOOKUP($C7,Mensual!$D$6:$H$163,5,0)) -> 1.0325 | H7: =+G7*B7 -> 0.10325
B8: 0.05 | C8: 1.6 Alquileres de contenedores secos (solo o en combos CONMOXA) | D8: =IF(VLOOKUP($C8,Mensual!$D$6:$G$163,2,0)<0,0,VLOOKUP($C8,Mensual!$D$6:$G$163,2,0)) -> Porcentaje | E8: =IF(VLOOKUP($C8,Mensual!$D$6:$G$163,3,0)<0,0,VLOOKUP($C8,Mensual!$D$6:$G$163,3,0)) -> 0.2 | F8: =IF(VLOOKUP($C8,Mensual!$D$6:$G$163,4,0)<0,0,VLOOKUP($C8,Mensual!$D$6:$G$163,4,0)) -> 0.45 | G8: =IF(VLOOKUP($C8,Mensual!$D$6:$H$163,5,0)<0,0,VLOOKUP($C8,Mensual!$D$6:$H$163,5,0)) -> 1 | H8: =+G8*B8 -> 0.05
B9: 0.05 | C9: 1.4 Lograr meta de ventas en alquileres de contenedores reefer (solo o en combo) | D9: =IF(VLOOKUP($C9,Mensual!$D$6:$G$163,2,0)<0,0,VLOOKUP($C9,Mensual!$D$6:$G$163,2,0)) -> Dólares | E9: =IF(VLOOKUP($C9,Mensual!$D$6:$G$163,3,0)<0,0,VLOOKUP($C9,Mensual!$D$6:$G$163,3,0)) -> 16000 | F9: =IF(VLOOKUP($C9,Mensual!$D$6:$G$163,4,0)<0,0,VLOOKUP($C9,Mensual!$D$6:$G$163,4,0)) -> 0 | G9: =IF(VLOOKUP($C9,Mensual!$D$6:$H$163,5,0)<0,0,VLOOKUP($C9,Mensual!$D$6:$H$163,5,0)) -> 0 | H9: =+G9*B9 -> 0
B10: 0.05 | C10: 1.3 Lograr meta de ventas contenedores secos y modificados(dolares) | D10: =IF(VLOOKUP($C10,Mensual!$D$6:$G$163,2,0)<0,0,VLOOKUP($C10,Mensual!$D$6:$G$163,2,0)) -> Dólares | E10: =IF(VLOOKUP($C10,Mensual!$D$6:$G$163,3,0)<0,0,VLOOKUP($C10,Mensual!$D$6:$G$163,3,0)) -> 40000 | F10: =IF(VLOOKUP($C10,Mensual!$D$6:$G$163,4,0)<0,0,VLOOKUP($C10,Mensual!$D$6:$G$163,4,0)) -> 1800 | G10: =IF(VLOOKUP($C10,Mensual!$D$6:$H$163,5,0)<0,0,VLOOKUP($C10,Mensual!$D$6:$H$163,5,0)) -> 0.045 | H10: =+G10*B10 -> 0.00225
B11: 0.05 | C11: 2.5 Aumentar Margen neto en venta de contenedores (modificados y secos) | D11: =IF(VLOOKUP($C11,Mensual!$D$6:$G$163,2,0)<0,0,VLOOKUP($C11,Mensual!$D$6:$G$163,2,0)) -> % | E11: =IF(VLOOKUP($C11,Mensual!$D$6:$G$163,3,0)<0,0,VLOOKUP($C11,Mensual!$D$6:$G$163,3,0)) -> 0.1 | F11: =IF(VLOOKUP($C11,Mensual!$D$6:$G$163,4,0)<0,0,VLOOKUP($C11,Mensual!$D$6:$G$163,4,0)) -> 0 | G11: =IF(VLOOKUP($C11,Mensual!$D$6:$H$163,5,0)<0,0,VLOOKUP($C11,Mensual!$D$6:$H$163,5,0)) -> 0 | H11: =+G11*B11 -> 0
B12: 0.05 | C12: 2.6 Aumento en 20% en margen de contribución bruta venta de contenedores | D12: =IF(VLOOKUP($C12,Mensual!$D$6:$G$163,2,0)<0,0,VLOOKUP($C12,Mensual!$D$6:$G$163,2,0)) -> $ | E12: =IF(VLOOKUP($C12,Mensual!$D$6:$G$163,3,0)<0,0,VLOOKUP($C12,Mensual!$D$6:$G$163,3,0)) -> 0.2 | F12: =IF(VLOOKUP($C12,Mensual!$D$6:$G$163,4,0)<0,0,VLOOKUP($C12,Mensual!$D$6:$G$163,4,0)) -> 0 | G12: =IF(VLOOKUP($C12,Mensual!$D$6:$H$163,5,0)<0,0,VLOOKUP($C12,Mensual!$D$6:$H$163,5,0)) -> 0 | H12: =+G12*B12 -> 0
B13: 0.25 | C13: 1.10 Aumentar ventas en articulos Sejue/get504 | D13: =IF(VLOOKUP($C13,Mensual!$D$6:$G$163,2,0)<0,0,VLOOKUP($C13,Mensual!$D$6:$G$163,2,0)) -> Articulos | E13: =IF(VLOOKUP($C13,Mensual!$D$6:$G$163,3,0)<0,0,VLOOKUP($C13,Mensual!$D$6:$G$163,3,0)) -> 10 | F13: =IF(VLOOKUP($C13,Mensual!$D$6:$G$163,4,0)<0,0,VLOOKUP($C13,Mensual!$D$6:$G$163,4,0)) -> 19 | G13: =IF(VLOOKUP($C13,Mensual!$D$6:$H$163,5,0)<0,0,VLOOKUP($C13,Mensual!$D$6:$H$163,5,0)) -> 1 | H13: =+G13*B13 -> 0.25
B14: 0.05 | C14: 2.8 Aumento en 20% en margen de contribución bruta alquiler de reefers. | D14: =IF(VLOOKUP($C14,Mensual!$D$6:$G$163,2,0)<0,0,VLOOKUP($C14,Mensual!$D$6:$G$163,2,0)) -> $ | E14: =IF(VLOOKUP($C14,Mensual!$D$6:$G$163,3,0)<0,0,VLOOKUP($C14,Mensual!$D$6:$G$163,3,0)) -> 0.2 | F14: =IF(VLOOKUP($C14,Mensual!$D$6:$G$163,4,0)<0,0,VLOOKUP($C14,Mensual!$D$6:$G$163,4,0)) -> 0 | G14: =IF(VLOOKUP($C14,Mensual!$D$6:$H$163,5,0)<0,0,VLOOKUP($C14,Mensual!$D$6:$H$163,5,0)) -> 0 | H14: =+G14*B14 -> 0
B15: 0.05 | C15: 2.7 Aumento en 20% en margen de contribución bruta alquiler de bodegas | D15: =IF(VLOOKUP($C15,Mensual!$D$6:$G$163,2,0)<0,0,VLOOKUP($C15,Mensual!$D$6:$G$163,2,0)) -> $ | E15: =IF(VLOOKUP($C15,Mensual!$D$6:$G$163,3,0)<0,0,VLOOKUP($C15,Mensual!$D$6:$G$163,3,0)) -> 0.2 | F15: =IF(VLOOKUP($C15,Mensual!$D$6:$G$163,4,0)<0,0,VLOOKUP($C15,Mensual!$D$6:$G$163,4,0)) -> 0 | G15: =IF(VLOOKUP($C15,Mensual!$D$6:$H$163,5,0)<0,0,VLOOKUP($C15,Mensual!$D$6:$H$163,5,0)) -> 0 | H15: =+G15*B15 -> 0
B16: =SUM(B6:B15) -> 1 | H16: =SUM(H6:H15) -> 0.4255

Sheet Nancy Garcia b (4)
I1: 0.9
C2: Departamento: | D2: Administracion | I2: 80-90%
C3: Colaborador: | D3: Nancy Garcia | I3: Menos de 80%
A5: =+Mensual!B5 -> No | B5: =+Mensual!C5 -> Peso | D5: =+Mensual!E5 -> Unidad de medición | E5: =+Mensual!F5 -> Meta | F5: =+Mensual!G5 -> Resultado | G5: =+Mensual!H5 -> Nota | H5: =+Mensual!I5 -> Valor ponderado | I5: =+Mensual!J5 -> 0 | J5: =+Mensual!K5 -> 0.25 | K5: =+Mensual!L5 -> 0.5 | ... Q5: =+Mensual!R5 -> 0 | T5: Nota | U5: Nota
A6: =+Mensual!B6 -> 4 | B6: 0.38 | C6: 9. SCORE CARD Grupo EXA | D6: =IF(VLOOKUP($C6,Mensual!$D$6:$G$163,2,0)<0,0,VLOOKUP($C6,Mensual!$D$6:$G$163,2,0)) -> RESULTADO SCORECARD | E6: =IF(VLOOKUP($C6,Mensual!$D$6:$G$163,3,0)<0,0,VLOOKUP($C6,Mensual!$D$6:$G$163,3,0)) -> 1 | F6: =IF(VLOOKUP($C6,Mensual!$D$6:$G$163,4,0)<0,0,VLOOKUP($C6,Mensual!$D$6:$G$163,4,0)) -> 1.0325 | G6: =IF(VLOOKUP($C6,Mensual!$D$6:$H$163,5,0)<0,0,VLOOKUP($C6,Mensual!$D$6:$H$163,5,0)) -> 1.0325 | H6: =+G6*B6 -> 0.39235 | I6: =+Mensual!J6 -> 0 | J6: =+Mensual!K6 -> 0 | K6: =+Mensual!L6 -> 0 | L6: =+Mensual!M6 -> 0
B7: 0.03 | C7: 4. Aumentar clima laboral | D7: =IF(VLOOKUP($C7,Mensual!$D$6:$G$163,2,0)<0,0,VLOOKUP($C7,Mensual!$D$6:$G$163,2,0)) -> 0 | E7: =IF(VLOOKUP($C7,Mensual!$D$6:$G$163,3,0)<0,0,VLOOKUP($C7,Mensual!$D$6:$G$163,3,0)) -> 0.1 | F7: =IF(VLOOKUP($C7,Mensual!$D$6:$G$163,4,0)<0,0,VLOOKUP($C7,Mensual!$D$6:$G$163,4,0)) -> 0.1 | G7: =IF(VLOOKUP($C7,Mensual!$D$6:$H$163,5,0)<0,0,VLOOKUP($C7,Mensual!$D$6:$H$163,5,0)) -> 1 | H7: =+G7*B7 -> 0.03
B8: 0.03 | C8: 2.1 Reducir gasto administrativo x% | D8: =IF(VLOOKUP($C8,Mensual!$D$6:$G$163,2,0)<0,0,VLOOKUP($C8,Mensual!$D$6:$G$163,2,0)) -> % | E8: =IF(VLOOKUP($C8,Mensual!$D$6:$G$163,3,0)<0,0,VLOOKUP($C8,Mensual!$D$6:$G$163,3,0)) -> 0.1 | F8: =IF(VLOOKUP($C8,Mensual!$D$6:$G$163,4,0)<0,0,VLOOKUP($C8,Mensual!$D$6:$G$163,4,0)) -> 0.32 | G8: =IF(VLOOKUP($C8,Mensual!$D$6:$H$163,5,0)<0,0,VLOOKUP($C8,Mensual!$D$6:$H$163,5,0)) -> 1 | H8: =+G8*B8 -> 0.03
B9: 0.03 | C9: 3.5 Multas ambientales y fiscales. | D9: =IF(VLOOKUP($C9,Mensual!$D$6:$G$163,2,0)<0,0,VLOOKUP($C9,Mensual!$D$6:$G$163,2,0)) -> 0 | E9: =IF(VLOOKUP($C9,Mensual!$D$6:$G$163,3,0)<0,0,VLOOKUP($C9,Mensual!$D$6:$G$163,3,0)) -> 0 | F9: =IF(VLOOKUP($C9,Mensual!$D$6:$G$163,4,0)<0,0,VLOOKUP($C9,Mensual!$D$6:$G$163,4,0)) -> 0 | G9: =IF(VLOOKUP($C9,Mensual!$D$6:$H$163,5,0)<0,0,VLOOKUP($C9,Mensual!$D$6:$H$163,5,0)) -> 1 | H9: =+G9*B9 -> 0.03
B10: 0.03 | C10: 6.1 Aumentar Rotación de inventario. | D10: =IF(VLOOKUP($C10,Mensual!$D$6:$G$163,2,0)<0,0,VLOOKUP($C10,Mensual!$D$6:$G$163,2,0)) -> 0 | E10: =IF(VLOOKUP($C10,Mensual!$D$6:$G$163,3,0)<0,0,VLOOKUP($C10,Mensual!$D$6:$G$163,3,0)) -> 0.05 | F10: =IF(VLOOKUP($C10,Mensual!$D$6:$G$163,4,0)<0,0,VLOOKUP($C10,Mensual!$D$6:$G$163,4,0)) -> 0 | G10: =IF(VLOOKUP($C10,Mensual!$D$6:$H$163,5,0)<0,0,VLOOKUP($C10,Mensual!$D$6:$H$163,5,0)) -> 0 | H10: =+G10*B10 -> 0
B11: 0.03 | C11: 7.1 Rotación de cuentas por cobrar. | D11: =IF(VLOOKUP($C11,Mensual!$D$6:$G$163,2,0)<0,0,VLOOKUP($C11,Mensual!$D$6:$G$163,2,0)) -> 0 | E11: =IF(VLOOKUP($C11,Mensual!$D$6:$G$163,3,0)<0,0,VLOOKUP($C11,Mensual!$D$6:$G$163,3,0)) -> 0.1 | F11: =IF(VLOOKUP($C11,Mensual!$D$6:$G$163,4,0)<0,0,VLOOKUP($C11,Mensual!$D$6:$G$163,4,0)) -> 0 | G11: =IF(VLOOKUP($C11,Mensual!$D$6:$H$163,5,0)<0,0,VLOOKUP($C11,Mensual!$D$6:$H$163,5,0)) -> 0 | H11: =+G11*B11 -> 0
B12: 0.03 | C12: 7.2 95% de clientes activos dentro del periodo de recuperacion | D12: =IF(VLOOKUP($C12,Mensual!$D$6:$G$163,2,0)<0,0,VLOOKUP($C12,Mensual!$D$6:$G$163,2,0)) -> 0 | E12: =IF(VLOOKUP($C12,Mensual!$D$6:$G$163,3,0)<0,0,VLOOKUP($C12,Mensual!$D$6:$G$163,3,0)) -> 0.2 | F12: =IF(VLOOKUP($C12,Mensual!$D$6:$G$163,4,0)<0,0,VLOOKUP($C12,Mensual!$D$6:$G$163,4,0)) -> 0 | G12: =IF(VLOOKUP($C12,Mensual!$D$6:$H$163,5,0)<0,0,VLOOKUP($C12,Mensual!$D$6:$H$163,5,0)) -> 0 | H12: =+G12*B12 -> 0
B13: 0.03 | C13: 2.3 Reducir Costo por km cabezales propios. | D13: =IF(VLOOKUP($C13,Mensual!$D$6:$G$163,2,0)<0,0,VLOOKUP($C13,Mensual!$D$6:$G$163,2,0)) -> $ | E13: =IF(VLOOKUP($C13,Mensual!$D$6:$G$163,3,0)<0,0,VLOOKUP($C13,Mensual!$D$6:$G$163,3,0)) -> 0.05 | F13: =IF(VLOOKUP($C13,Mensual!$D$6:$G$163,4,0)<0,0,VLOOKUP($C13,Mensual!$D$6:$G$163,4,0)) -> 0.6 | G13: =IF(VLOOKUP($C13,Mensual!$D$6:$H$163,5,0)<0,0,VLOOKUP($C13,Mensual!$D$6:$H$163,5,0)) -> 1 | H13: =+G13*B13 -> 0.03
B14: 0.03 | C14: 5.2 Productividad cabezales Flota Nueva | D14: =IF(VLOOKUP($C14,Mensual!$D$6:$G$163,2,0)<0,0,VLOOKUP($C14,Mensual!$D$6:$G$163,2,0)) -> 0 | E14: =IF(VLOOKUP($C14,Mensual!$D$6:$G$163,3,0)<0,0,VLOOKUP($C14,Mensual!$D$6:$G$163,3,0)) -> 4500 | F14: =IF(VLOOKUP($C14,Mensual!$D$6:$G$163,4,0)<0,0,VLOOKUP($C14,Mensual!$D$6:$G$163,4,0)) -> 4782 | G14: =IF(VLOOKUP($C14,Mensual!$D$6:$H$163,5,0)<0,0,VLOOKUP($C14,Mensual!$D$6:$H$163,5,0)) -> 1 | H14: =+G14*B14 -> 0.03
B15: 0.03 | C15: 6.2 Disminuir a 5% el desuso de los chasis (equipos con mas de 30 dias en las yardas) | D15: =IF(VLOOKUP($C15,Mensual!$D$6:$G$163,2,0)<0,0,VLOOKUP($C15,Mensual!$D$6:$G$163,2,0)) -> % | E15: =IF(VLOOKUP($C15,Mensual!$D$6:$G$163,3,0)<0,0,VLOOKUP($C15,Mensual!$D$6:$G$163,3,0)) -> 0.05 | F15: =IF(VLOOKUP($C15,Mensual!$D$6:$G$163,4,0)<0,0,VLOOKUP($C15,Mensual!$D$6:$G$163,4,0)) -> 0.05 | G15: =IF(VLOOKUP($C15,Mensual!$D$6:$H$163,5,0)<0,0,VLOOKUP($C15,Mensual!$D$6:$H$163,5,0)) -> 1 | H15: =+G15*B15 -> 0.03
B16: 0.03 | C16: 6.5 Disminuir a 0-1 el desuso de cabezales propios | D16: =IF(VLOOKUP($C16,Mensual!$D$6:$G$163,2,0)<0,0,VLOOKUP($C16,Mensual!$D$6:$G$163,2,0)) -> cabezal | E16: =IF(VLOOKUP($C16,Mensual!$D$6:$G$163,3,0)<0,0,VLOOKUP($C16,Mensual!$D$6:$G$163,3,0)) -> 1 | F16: =IF(VLOOKUP($C16,Mensual!$D$6:$G$163,4,0)<0,0,VLOOKUP($C16,Mensual!$D$6:$G$163,4,0)) -> 1 | G16: =IF(VLOOKUP($C16,Mensual!$D$6:$H$163,5,0)<0,0,VLOOKUP($C16,Mensual!$D$6:$H$163,5,0)) -> 0 | H16: =+G16*B16 -> 0
B17: 0.08 | C17: 7. Disminuir el D/E | D17: =IF(VLOOKUP($C17,Mensual!$D$6:$G$163,2,0)<0,0,VLOOKUP($C17,Mensual!$D$6:$G$163,2,0)) -> 0 | E17: =IF(VLOOKUP($C17,Mensual!$D$6:$G$163,3,0)<0,0,VLOOKUP($C17,Mensual!$D$6:$G$163,3,0)) -> 0.05 | F17: =IF(VLOOKUP($C17,Mensual!$D$6:$G$163,4,0)<0,0,VLOOKUP($C17,Mensual!$D$6:$G$163,4,0)) -> 0.05 | G17: =IF(VLOOKUP($C17,Mensual!$D$6:$H$163,5,0)<0,0,VLOOKUP($C17,Mensual!$D$6:$H$163,5,0)) -> 1 | H17: =+G17*B17 -> 0.08
B18: 0.08 | C18: 6. Aumentar el ROA | D18: =IF(VLOOKUP($C18,Mensual!$D$6:$G$163,2,0)<0,0,VLOOKUP($C18,Mensual!$D$6:$G$163,2,0)) -> 0 | E18: =IF(VLOOKUP($C18,Mensual!$D$6:$G$163,3,0)<0,0,VLOOKUP($C18,Mensual!$D$6:$G$163,3,0)) -> 0.05 | F18: =IF(VLOOKUP($C18,Mensual!$D$6:$G$163,4,0)<0,0,VLOOKUP($C18,Mensual!$D$6:$G$163,4,0)) -> 1 | G18: =IF(VLOOKUP($C18,Mensual!$D$6:$H$163,5,0)<0,0,VLOOKUP($C18,Mensual!$D$6:$H$163,5,0)) -> 1 | H18: =+G18*B18 -> 0.08
... B21: 0.03 | C21: 2.3 Reducir Costo por km cabezales propios. | D21: =IF(VLOOKUP($C21,Mensual!$D$6:$G$163,2,0)<0,0,VLOOKUP($C21,Mensual!$D$6:$G$163,2,0)) -> $ | E21: =IF(VLOOKUP($C21,Mensual!$D$6:$G$163,3,0)<0,0,VLOOKUP($C21,Mensual!$D$6:$G$163,3,0)) -> 0.05 | F21: =IF(VLOOKUP($C21,Mensual!$D$6:$G$163,4,0)<0,0,VLOOKUP($C21,Mensual!$D$6:$G$163,4,0)) -> 0.6 | G21: =IF(VLOOKUP($C21,Mensual!$D$6:$H$163,5,0)<0,0,VLOOKUP($C21,Mensual!$D$6:$H$163,5,0)) -> 1 | H21: =+G21*B21 -> 0.03
B22: =SUM(B6:B21) -> 1 | H22: =SUM(H6:H21) -> 0.89235

Sheet David Molina
I1: 0.9
C2: Colaborador: | D2: David Molina | I2: 80-90%
C3: Departamento: | D3: SistemasYProcesos | I3: Menos de 80%
A5: =+Mensual!B5 -> No | B5: =+Mensual!C5 -> Peso | D5: =+Mensual!E5 -> Unidad de medición | E5: =+Mensual!F5 -> Meta | F5: =+Mensual!G5 -> Resultado | G5: =+Mensual!H5 -> Nota | H5: =+Mensual!I5 -> Valor ponderado | I5: =+Mensual!J5 -> 0 | J5: =+Mensual!K5 -> 0.25 | K5: =+Mensual!L5 -> 0.5 | ... Q5: =+Mensual!R5 -> 0 | T5: Nota | U5: Nota
A6: =+Mensual!B6 -> 4 | B6: 0.55 | C6: 9. SCORE CARD Grupo EXA | D6: =IF(VLOOKUP($C6,Mensual!$D$6:$G$163,2,0)<0,0,VLOOKUP($C6,Mensual!$D$6:$G$163,2,0)) -> RESULTADO SCORECARD | E6: =IF(VLOOKUP($C6,Mensual!$D$6:$G$163,3,0)<0,0,VLOOKUP($C6,Mensual!$D$6:$G$163,3,0)) -> 1 | F6: =IF(VLOOKUP($C6,Mensual!$D$6:$G$163,4,0)<0,0,VLOOKUP($C6,Mensual!$D$6:$G$163,4,0)) -> 1.0325 | G6: =IF(VLOOKUP($C6,Mensual!$D$6:$H$163,5,0)<0,0,VLOOKUP($C6,Mensual!$D$6:$H$163,5,0)) -> 1.0325 | H6: =+G6*B6 -> 0.567875 | I6: =+Mensual!J6 -> 0 | J6: =+Mensual!K6 -> 0 | K6: =+Mensual!L6 -> 0 | L6: =+Mensual!M6 -> 0
B7: 0.05 | C7: 3. Cero incidentes mayores de seguridad y sostenibilidad | D7: =IF(VLOOKUP($C7,Mensual!$D$6:$G$163,2,0)<0,0,VLOOKUP($C7,Mensual!$D$6:$G$163,2,0)) -> 0 | E7: =IF(VLOOKUP($C7,Mensual!$D$6:$G$163,3,0)<0,0,VLOOKUP($C7,Mensual!$D$6:$G$163,3,0)) -> 1 | F7: =IF(VLOOKUP($C7,Mensual!$D$6:$G$163,4,0)<0,0,VLOOKUP($C7,Mensual!$D$6:$G$163,4,0)) -> 1 | G7: =IF(VLOOKUP($C7,Mensual!$D$6:$H$163,5,0)<0,0,VLOOKUP($C7,Mensual!$D$6:$H$163,5,0)) -> 1 | H7: =+G7*B7 -> 0.05
B8: 0.25 | C8: 8. Innovaciones estratégicas de sistemas de Impacto recurrente | D8: =IF(VLOOKUP($C8,Mensual!$D$6:$G$163,2,0)<0,0,VLOOKUP($C8,Mensual!$D$6:$G$163,2,0)) -> 0 | E8: =IF(VLOOKUP($C8,Mensual!$D$6:$G$163,3,0)<0,0,VLOOKUP($C8,Mensual!$D$6:$G$163,3,0)) -> 1 | F8: =IF(VLOOKUP($C8,Mensual!$D$6:$G$163,4,0)<0,0,VLOOKUP($C8,Mensual!$D$6:$G$163,4,0)) -> 1 | G8: =IF(VLOOKUP($C8,Mensual!$D$6:$H$163,5,0)<0,0,VLOOKUP($C8,Mensual!$D$6:$H$163,5,0)) -> 1 | H8: =+G8*B8 -> 0.25
B9: 0.05 | C9: 5.6 Aprovechamiento GPS | D9: =IF(VLOOKUP($C9,Mensual!$D$6:$G$163,2,0)<0,0,VLOOKUP($C9,Mensual!$D$6:$G$163,2,0)) -> 0 | E9: =IF(VLOOKUP($C9,Mensual!$D$6:$G$163,3,0)<0,0,VLOOKUP($C9,Mensual!$D$6:$G$163,3,0)) -> 0.9 | F9: =IF(VLOOKUP($C9,Mensual!$D$6:$G$163,4,0)<0,0,VLOOKUP($C9,Mensual!$D$6:$G$163,4,0)) -> 0.82 | G9: =IF(VLOOKUP($C9,Mensual!$D$6:$H$163,5,0)<0,0,VLOOKUP($C9,Mensual!$D$6:$H$163,5,0)) -> 0.91111111 | H9: =+G9*B9 -> 0.045555556
B10: 0.1 | C10: 5. Productividad | D10: =IF(VLOOKUP($C10,Mensual!$D$6:$G$163,2,0)<0,0,VLOOKUP($C10,Mensual!$D$6:$G$163,2,0)) -> 0 | E10: =IF(VLOOKUP($C10,Mensual!$D$6:$G$163,3,0)<0,0,VLOOKUP($C10,Mensual!$D$6:$G$163,3,0)) -> 3700 | F10: =IF(VLOOKUP($C10,Mensual!$D$6:$G$163,4,0)<0,0,VLOOKUP($C10,Mensual!$D$6:$G$163,4,0)) -> 3932 | G10: =IF(VLOOKUP($C10,Mensual!$D$6:$H$163,5,0)<0,0,VLOOKUP($C10,Mensual!$D$6:$H$163,5,0)) -> 1 | H10: =+G10*B10 -> 0.1
B11: =SUM(B6:B10) -> 1 | H11: =SUM(H6:H10) -> 1.0134306
B14: Resultados
B15: =+B5 -> Peso | C15: =+C5 -> 0 | D15: =+D5 -> Unidad de medición | E15: =+E5 -> Meta | F15: ENERO | G15: febrero | H15: marzo | I15: abril | J15: mayo | K15: junio | L15: julio | M15: agosto | N15: septiembre | O15: octubre | P15: noviembre | Q15: diciembre
B16: =+B6 -> 0.55 | C16: =+C6 -> 9. SCORE CARD Grupo EXA | D16: =+D6 -> RESULTADO SCORECARD | E16: =+E6 -> 1 | F16: =+F6 -> 1.0325
B17: =+B7 -> 0.05 | C17: =+C7 -> 3. Cero incidentes mayores de seguridad y sostenibilidad | D17: =+D7 -> 0 | E17: =+E7 -> 1 | F17: =+F7 -> 1
B18: =+B8 -> 0.25 | C18: =+C8 -> 8. Innovaciones estratégicas de sistemas de Impacto recurrente | D18: =+D8 -> 0 | E18: =+E8 -> 1 | F18: =+F8 -> 1
B19: =+B9 -> 0.05 | C19: =+C9 -> 5.6 Aprovechamiento GPS | D19: =+D9 -> 0 | E19: =+E9 -> 0.9 | F19: =+F9 -> 0.82
B20: =+B10 -> 0.1 | C20: =+C10 -> 5. Productividad | D20: =+D10 -> 0 | E20: =+E10 -> 3700 | F20: =+F10 -> 3932
B21: =SUM(B16:B20) -> 1
B24: SCORECARD
B26: Resultados
B27: =+Mensual!C27 -> 0.275 | D27: =+Mensual!E27 -> 0 | F27: enero | G27: febrero | H27: marzo | I27: abril | J27: mayo | K27: junio | L27: julio | M27: agosto | N27: septiembre | O27: octubre | P27: noviembre | Q27: diciembre
B28: 0.55 | C28: 9. SCORE CARD Grupo EXA | D28: =IF(VLOOKUP($C28,Mensual!$D$6:$G$163,2,0)<0,0,VLOOKUP($C28,Mensual!$D$6:$G$163,2,0)) -> RESULTADO SCORECARD | E28: =IF(VLOOKUP($C28,Mensual!$D$6:$G$163,3,0)<0,0,VLOOKUP($C28,Mensual!$D$6:$G$163,3,0)) -> 1 | F28: =IF(VLOOKUP($C28,Mensual!$D$6:$G$163,4,0)<0,0,VLOOKUP($C28,Mensual!$D$6:$G$163,4,0)) -> 1.0325
B29: 0.05 | C29: 3. Cero incidentes mayores de seguridad y sostenibilidad | D29: =IF(VLOOKUP($C29,Mensual!$D$6:$G$163,2,0)<0,0,VLOOKUP($C29,Mensual!$D$6:$G$163,2,0)) -> 0 | E29: =IF(VLOOKUP($C29,Mensual!$D$6:$G$163,3,0)<0,0,VLOOKUP($C29,Mensual!$D$6:$G$163,3,0)) -> 1 | F29: =IF(VLOOKUP($C29,Mensual!$D$6:$G$163,4,0)<0,0,VLOOKUP($C29,Mensual!$D$6:$G$163,4,0)) -> 1
B30: 0.25 | C30: 8. Innovaciones estratégicas de sistemas de Impacto recurrente | D30: =IF(VLOOKUP($C30,Mensual!$D$6:$G$163,2,0)<0,0,VLOOKUP($C30,Mensual!$D$6:$G$163,2,0)) -> 0 | E30: =IF(VLOOKUP($C30,Mensual!$D$6:$G$163,3,0)<0,0,VLOOKUP($C30,Mensual!$D$6:$G$163,3,0)) -> 1 | F30: =IF(VLOOKUP($C30,Mensual!$D$6:$G$163,4,0)<0,0,VLOOKUP($C30,Mensual!$D$6:$G$163,4,0)) -> 1
B31: 0.05 | C31: 5.6 Aprovechamiento GPS | D31: =IF(VLOOKUP($C31,Mensual!$D$6:$G$163,2,0)<0,0,VLOOKUP($C31,Mensual!$D$6:$G$163,2,0)) -> 0 | E31: =IF(VLOOKUP($C31,Mensual!$D$6:$G$163,3,0)<0,0,VLOOKUP($C31,Mensual!$D$6:$G$163,3,0)) -> 0.9 | F31: =IF(VLOOKUP($C31,Mensual!$D$6:$G$163,4,0)<0,0,VLOOKUP($C31,Mensual!$D$6:$G$163,4,0)) -> 0.82
B32: 0.1 | C32: 5. Productividad | D32: =IF(VLOOKUP($C32,Mensual!$D$6:$G$163,2,0)<0,0,VLOOKUP($C32,Mensual!$D$6:$G$163,2,0)) -> 0 | E32: =IF(VLOOKUP($C32,Mensual!$D$6:$G$163,3,0)<0,0,VLOOKUP($C32,Mensual!$D$6:$G$163,3,0)) -> 3700 | F32: =IF(VLOOKUP($C32,Mensual!$D$6:$G$163,4,0)<0,0,VLOOKUP($C32,Mensual!$D$6:$G$163,4,0)) -> 3932
B33: =SUM(B28:B32) -> 1

Sheet Desarrollo
I1: 0.9
I2: 80-90%
C3: Departamento: | D3: Sistemas_Y_Procesos | I3: Menos de 80%
A5: =+Mensual!B5 -> No | B5: =+Mensual!C5 -> Peso | D5: =+Mensual!E5 -> Unidad de medición | E5: =+Mensual!F5 -> Meta | F5: =+Mensual!G5 -> Resultado | G5: =+Mensual!H5 -> Nota | H5: =+Mensual!I5 -> Valor ponderado | I5: =+Mensual!J5 -> 0 | J5: =+Mensual!K5 -> 0.25 | K5: =+Mensual!L5 -> 0.5 | ... Q5: =+Mensual!R5 -> 0 | T5: Nota | U5: Nota
A6: =+Mensual!B6 -> 4 | B6: 0.3 | C6: 9. SCORE CARD Grupo EXA | D6: =IF(VLOOKUP($C6,Mensual!$D$6:$G$163,2,0)<0,0,VLOOKUP($C6,Mensual!$D$6:$G$163,2,0)) -> RESULTADO SCORECARD | E6: =IF(VLOOKUP($C6,Mensual!$D$6:$G$163,3,0)<0,0,VLOOKUP($C6,Mensual!$D$6:$G$163,3,0)) -> 1 | F6: =IF(VLOOKUP($C6,Mensual!$D$6:$G$163,4,0)<0,0,VLOOKUP($C6,Mensual!$D$6:$G$163,4,0)) -> 1.0325 | G6: =IF(VLOOKUP($C6,Mensual!$D$6:$H$163,5,0)<0,0,VLOOKUP($C6,Mensual!$D$6:$H$163,5,0)) -> 1.0325 | H6: =+G6*B6 -> 0.30975 | I6: =+Mensual!J6 -> 0 | J6: =+Mensual!K6 -> 0 | K6: =+Mensual!L6 -> 0 | L6: =+Mensual!M6 -> 0
B7: 0.6 | C7: 8. Innovaciones estratégicas de sistemas de Impacto recurrente | D7: =IF(VLOOKUP($C7,Mensual!$D$6:$G$135,2,0)<0,0,VLOOKUP($C7,Mensual!$D$6:$G$135,2,0)) -> 0 | E7: =IF(VLOOKUP($C7,Mensual!$D$6:$G$163,3,0)<0,0,VLOOKUP($C7,Mensual!$D$6:$G$163,3,0)) -> 1 | F7: =IF(VLOOKUP($C7,Mensual!$D$6:$G$163,4,0)<0,0,VLOOKUP($C7,Mensual!$D$6:$G$163,4,0)) -> 1 | G7: =IF(VLOOKUP($C7,Mensual!$D$6:$H$163,5,0)<0,0,VLOOKUP($C7,Mensual!$D$6:$H$163,5,0)) -> 1 | H7: =+G7*B7 -> 0.6
B8: 0.1 | C8: 5. Productividad | E8: =IF(VLOOKUP($C8,Mensual!$D$6:$G$163,3,0)<0,0,VLOOKUP($C8,Mensual!$D$6:$G$163,3,0)) -> 3700 | F8: =IF(VLOOKUP($C8,Mensual!$D$6:$G$163,4,0)<0,0,VLOOKUP($C8,Mensual!$D$6:$G$163,4,0)) -> 3932 | G8: =IF(VLOOKUP($C8,Mensual!$D$6:$H$163,5,0)<0,0,VLOOKUP($C8,Mensual!$D$6:$H$163,5,0)) -> 1 | H8: =+G8*B8 -> 0.1
B9: =SUM(B6:B8) -> 1 | H9: =SUM(H6:H8) -> 1.00975
C13: Colaboradores
C14: Cristian Hernandez
C15: Oscar Romero

Sheet Yadira
I1: 0.9
C2: Colaborador: | D2: Yadira Reyes | I2: 80-90%
C3: Departamento: | D3: Sistemas_Y_Procesos | I3: Menos de 80%
A5: =+Mensual!B5 -> No | B5: =+Mensual!C5 -> Peso | D5: =+Mensual!E5 -> Unidad de medición | E5: =+Mensual!F5 -> Meta | F5: =+Mensual!G5 -> Resultado | G5: =+Mensual!H5 -> Nota | H5: =+Mensual!I5 -> Valor ponderado | I5: =+Mensual!J5 -> 0 | J5: =+Mensual!K5 -> 0.25 | K5: =+Mensual!L5 -> 0.5 | ... Q5: =+Mensual!R5 -> 0 | T5: Nota | U5: Nota
B6: 0.25 | C6: 9. SCORE CARD Grupo EXA | D6: =IF(VLOOKUP($C6,Mensual!$D$6:$G$163,2,0)<0,0,VLOOKUP($C6,Mensual!$D$6:$G$163,2,0)) -> RESULTADO SCORECARD | E6: =IF(VLOOKUP($C6,Mensual!$D$6:$G$163,3,0)<0,0,VLOOKUP($C6,Mensual!$D$6:$G$163,3,0)) -> 1 | F6: =IF(VLOOKUP($C6,Mensual!$D$6:$G$163,4,0)<0,0,VLOOKUP($C6,Mensual!$D$6:$G$163,4,0)) -> 1.0325 | G6: =IF(VLOOKUP($C6,Mensual!$D$6:$H$163,5,0)<0,0,VLOOKUP($C6,Mensual!$D$6:$H$163,5,0)) -> 1.0325 | H6: =+G6*B6 -> 0.258125 | I6: =+Mensual!J6 -> 0 | J6: =+Mensual!K6 -> 0 | K6: =+Mensual!L6 -> 0 | L6: =+Mensual!M6 -> 0
B7: 0.05 | C7: 3. Cero incidentes mayores de seguridad y sostenibilidad | D7: =IF(VLOOKUP($C7,Mensual!$D$6:$G$135,2,0)<0,0,VLOOKUP($C7,Mensual!$D$6:$G$135,2,0)) -> 0 | E7: =IF(VLOOKUP($C7,Mensual!$D$6:$G$163,3,0)<0,0,VLOOKUP($C7,Mensual!$D$6:$G$163,3,0)) -> 1 | F7: =IF(VLOOKUP($C7,Mensual!$D$6:$G$163,4,0)<0,0,VLOOKUP($C7,Mensual!$D$6:$G$163,4,0)) -> 1 | G7: =IF(VLOOKUP($C7,Mensual!$D$6:$H$163,5,0)<0,0,VLOOKUP($C7,Mensual!$D$6:$H$163,5,0)) -> 1 | H7: =+G7*B7 -> 0.05
B8: 0.05 | C8: 5. Productividad | D8: =IF(VLOOKUP($C8,Mensual!$D$6:$G$135,2,0)<0,0,VLOOKUP($C8,Mensual!$D$6:$G$135,2,0)) -> 0 | E8: =IF(VLOOKUP($C8,Mensual!$D$6:$G$163,3,0)<0,0,VLOOKUP($C8,Mensual!$D$6:$G$163,3,0)) -> 3700 | F8: =IF(VLOOKUP($C8,Mensual!$D$6:$G$163,4,0)<0,0,VLOOKUP($C8,Mensual!$D$6:$G$163,4,0)) -> 3932 | G8: =IF(VLOOKUP($C8,Mensual!$D$6:$H$163,5,0)<0,0,VLOOKUP($C8,Mensual!$D$6:$H$163,5,0)) -> 1 | H8: =+G8*B8 -> 0.05
B9: 0.1 | C9: 2.21 Aumentar % neto del servicio de transporte | D9: =IF(VLOOKUP($C9,Mensual!$D$6:$G$135,2,0)<0,0,VLOOKUP($C9,Mensual!$D$6:$G$135,2,0)) -> 0 | E9: =IF(VLOOKUP($C9,Mensual!$D$6:$G$163,3,0)<0,0,VLOOKUP($C9,Mensual!$D$6:$G$163,3,0)) -> 0.1 | F9: =IF(VLOOKUP($C9,Mensual!$D$6:$G$163,4,0)<0,0,VLOOKUP($C9,Mensual!$D$6:$G$163,4,0)) -> 0.1 | G9: =IF(VLOOKUP($C9,Mensual!$D$6:$H$163,5,0)<0,0,VLOOKUP($C9,Mensual!$D$6:$H$163,5,0)) -> 1 | H9: =+G9*B9 -> 0.1
B10: 0.55 | C10: 5.7 Dias de facturacion | D10: =IF(VLOOKUP($C10,Mensual!$D$6:$G$135,2,0)<0,0,VLOOKUP($C10,Mensual!$D$6:$G$135,2,0)) -> 0 | E10: =IF(VLOOKUP($C10,Mensual!$D$6:$G$163,3,0)<0,0,VLOOKUP($C10,Mensual!$D$6:$G$163,3,0)) -> 4 | F10: =IF(VLOOKUP($C10,Mensual!$D$6:$G$163,4,0)<0,0,VLOOKUP($C10,Mensual!$D$6:$G$163,4,0)) -> 6 | G10: =IF(VLOOKUP($C10,Mensual!$D$6:$H$163,5,0)<0,0,VLOOKUP($C10,Mensual!$D$6:$H$163,5,0)) -> 1 | H10: =+G10*B10 -> 0.55
B11: =SUM(B6:B10) -> 1 | H11: =SUM(H6:H10) -> 1.008125
C21: Agrega el aprovechamiento de dispositivos

Sheet Keila
I1: 0.9
C2: Colaborador: | D2: Keila Rodriguez | I2: 80-90%
C3: Departamento: | D3: Sistemas_Y_Procesos | I3: Menos de 80%
A5: =+Mensual!B5 -> No | B5: =+Mensual!C5 -> Peso | D5: =+Mensual!E5 -> Unidad de medición | E5: =+Mensual!F5 -> Meta | F5: =+Mensual!G5 -> Resultado | G5: =+Mensual!H5 -> Nota | H5: =+Mensual!I5 -> Valor ponderado | I5: =+Mensual!J5 -> 0 | J5: =+Mensual!K5 -> 0.25 | K5: =+Mensual!L5 -> 0.5 | ... Q5: =+Mensual!R5 -> 0 | T5: Nota | U5: Nota
A6: =+Mensual!B6 -> 4 | B6: 0.25 | C6: 9. SCORE CARD Grupo EXA | D6: =IF(VLOOKUP($C6,Mensual!$D$6:$G$163,2,0)<0,0,VLOOKUP($C6,Mensual!$D$6:$G$163,2,0)) -> RESULTADO SCORECARD | E6: =IF(VLOOKUP($C6,Mensual!$D$6:$G$163,3,0)<0,0,VLOOKUP($C6,Mensual!$D$6:$G$163,3,0)) -> 1 | F6: =IF(VLOOKUP($C6,Mensual!$D$6:$G$163,4,0)<0,0,VLOOKUP($C6,Mensual!$D$6:$G$163,4,0)) -> 1.0325 | G6: =IF(VLOOKUP($C6,Mensual!$D$6:$H$163,5,0)<0,0,VLOOKUP($C6,Mensual!$D$6:$H$163,5,0)) -> 1.0325 | H6: =+G6*B6 -> 0.258125 | I6: =+Mensual!J6 -> 0 | J6: =+Mensual!K6 -> 0 | K6: =+Mensual!L6 -> 0 | L6: =+Mensual!M6 -> 0
B7: 0.05 | C7: 3. Cero incidentes mayores de seguridad y sostenibilidad | D7: =IF(VLOOKUP($C7,Mensual!$D$6:$G$135,2,0)<0,0,VLOOKUP($C7,Mensual!$D$6:$G$135,2,0)) -> 0 | E7: =IF(VLOOKUP($C7,Mensual!$D$6:$G$163,3,0)<0,0,VLOOKUP($C7,Mensual!$D$6:$G$163,3,0)) -> 1 | F7: =IF(VLOOKUP($C7,Mensual!$D$6:$G$163,4,0)<0,0,VLOOKUP($C7,Mensual!$D$6:$G$163,4,0)) -> 1 | G7: =IF(VLOOKUP($C7,Mensual!$D$6:$H$163,5,0)<0,0,VLOOKUP($C7,Mensual!$D$6:$H$163,5,0)) -> 1 | H7: =+G7*B7 -> 0.05
B8: 0.1 | C8: 1.9 Aumento en ventas de GPS a terceros (nuevos clientes) | D8: =IF(VLOOKUP($C8,Mensual!$D$6:$G$135,2,0)<0,0,VLOOKUP($C8,Mensual!$D$6:$G$135,2,0)) -> Unidad instaladas / mensuales | E8: =IF(VLOOKUP($C8,Mensual!$D$6:$G$163,3,0)<0,0,VLOOKUP($C8,Mensual!$D$6:$G$163,3,0)) -> 10 | F8: =IF(VLOOKUP($C8,Mensual!$D$6:$G$163,4,0)<0,0,VLOOKUP($C8,Mensual!$D$6:$G$163,4,0)) -> 0 | G8: =IF(VLOOKUP($C8,Mensual!$D$6:$H$163,5,0)<0,0,VLOOKUP($C8,Mensual!$D$6:$H$163,5,0)) -> 0 | H8: =+G8*B8 -> 0
B9: 0.5 | C9: 5.6 Aprovechamiento GPS | D9: =IF(VLOOKUP($C9,Mensual!$D$6:$G$135,2,0)<0,0,VLOOKUP($C9,Mensual!$D$6:$G$135,2,0)) -> 0 | E9: =IF(VLOOKUP($C9,Mensual!$D$6:$G$163,3,0)<0,0,VLOOKUP($C9,Mensual!$D$6:$G$163,3,0)) -> 0.9 | F9: =IF(VLOOKUP($C9,Mensual!$D$6:$G$163,4,0)<0,0,VLOOKUP($C9,Mensual!$D$6:$G$163,4,0)) -> 0.82 | G9: =IF(VLOOKUP($C9,Mensual!$D$6:$H$163,5,0)<0,0,VLOOKUP($C9,Mensual!$D$6:$H$163,5,0)) -> 0.91111111 | H9: =+G9*B9 -> 0.45555556
B10: 0.1 | C10: 2.12 Costo por mes por GPS (Costo de plataforma + Tigo/claro + otros costos) | D10: =IF(VLOOKUP($C10,Mensual!$D$6:$G$135,2,0)<0,0,VLOOKUP($C10,Mensual!$D$6:$G$135,2,0)) -> $ | E10: =IF(VLOOKUP($C10,Mensual!$D$6:$G$163,3,0)<0,0,VLOOKUP($C10,Mensual!$D$6:$G$163,3,0)) -> 8 | F10: =IF(VLOOKUP($C10,Mensual!$D$6:$G$163,4,0)<0,0,VLOOKUP($C10,Mensual!$D$6:$G$163,4,0)) -> 4.71 | G10: =IF(VLOOKUP($C10,Mensual!$D$6:$H$163,5,0)<0,0,VLOOKUP($C10,Mensual!$D$6:$H$163,5,0)) -> 1 | H10: =+G10*B10 -> 0.1
B11: =SUM(B6:B10) -> 1 | H11: =SUM(H6:H10) -> 0.86368056

Sheet Mario
I1: 0.9
C2: Colaborador: | D2: Mario Murillo | I2: 80-90%
C3: Departamento: | D3: Sistemas_Y_Procesos | I3: Menos de 80%
A5: =+Mensual!B5 -> No | B5: =+Mensual!C5 -> Peso | D5: =+Mensual!E5 -> Unidad de medición | E5: =+Mensual!F5 -> Meta | F5: =+Mensual!G5 -> Resultado | G5: =+Mensual!H5 -> Nota | H5: =+Mensual!I5 -> Valor ponderado | I5: =+Mensual!J5 -> 0 | J5: =+Mensual!K5 -> 0.25 | K5: =+Mensual!L5 -> 0.5 | ... Q5: =+Mensual!R5 -> 0 | T5: Nota | U5: Nota
A6: =+Mensual!B6 -> 4 | B6: 0.25 | C6: 9. SCORE CARD Grupo EXA | D6: =IF(VLOOKUP($C6,Mensual!$D$6:$G$163,2,0)<0,0,VLOOKUP($C6,Mensual!$D$6:$G$163,2,0)) -> RESULTADO SCORECARD | E6: =IF(VLOOKUP($C6,Mensual!$D$6:$G$163,3,0)<0,0,VLOOKUP($C6,Mensual!$D$6:$G$163,3,0)) -> 1 | F6: =IF(VLOOKUP($C6,Mensual!$D$6:$G$163,4,0)<0,0,VLOOKUP($C6,Mensual!$D$6:$G$163,4,0)) -> 1.0325 | G6: =IF(VLOOKUP($C6,Mensual!$D$6:$H$163,5,0)<0,0,VLOOKUP($C6,Mensual!$D$6:$H$163,5,0)) -> 1.0325 | H6: =+G6*B6 -> 0.258125 | I6: =+Mensual!J6 -> 0 | J6: =+Mensual!K6 -> 0 | K6: =+Mensual!L6 -> 0 | L6: =+Mensual!M6 -> 0
B7: 0.15 | C7: 4. Aumentar clima laboral | D7: =IF(VLOOKUP($C7,Mensual!$D$6:$G$135,2,0)<0,0,VLOOKUP($C7,Mensual!$D$6:$G$135,2,0)) -> 0 | E7: =IF(VLOOKUP($C7,Mensual!$D$6:$G$163,3,0)<0,0,VLOOKUP($C7,Mensual!$D$6:$G$163,3,0)) -> 0.1 | F7: =IF(VLOOKUP($C7,Mensual!$D$6:$G$163,4,0)<0,0,VLOOKUP($C7,Mensual!$D$6:$G$163,4,0)) -> 0.1 | G7: =IF(VLOOKUP($C7,Mensual!$D$6:$H$163,5,0)<0,0,VLOOKUP($C7,Mensual!$D$6:$H$163,5,0)) -> 1 | H7: =+G7*B7 -> 0.15
B8: 0.6 | C8: 3. Cero incidentes mayores de seguridad y sostenibilidad | D8: =IF(VLOOKUP($C8,Mensual!$D$6:$G$135,2,0)<0,0,VLOOKUP($C8,Mensual!$D$6:$G$135,2,0)) -> 0 | E8: =IF(VLOOKUP($C8,Mensual!$D$6:$G$163,3,0)<0,0,VLOOKUP($C8,Mensual!$D$6:$G$163,3,0)) -> 1 | F8: =IF(VLOOKUP($C8,Mensual!$D$6:$G$163,4,0)<0,0,VLOOKUP($C8,Mensual!$D$6:$G$163,4,0)) -> 1 | G8: =IF(VLOOKUP($C8,Mensual!$D$6:$H$163,5,0)<0,0,VLOOKUP($C8,Mensual!$D$6:$H$163,5,0)) -> 1 | H8: =+G8*B8 -> 0.6
B9: =SUM(B6:B8) -> 1 | H9: =SUM(H6:H8) -> 1.008125

Sheet Luis Madrid
I1: 0.9
C2: Colaborador: | D2: Luis Madrid | I2: 80-90%
C3: Departamento: | D3: Contenedores | I3: Menos de 80%
A5: =+Mensual!B5 -> No | B5: =+Mensual!C5 -> Peso | D5: =+Mensual!E5 -> Unidad de medición | E5: =+Mensual!F5 -> Meta | F5: =+Mensual!G5 -> Resultado | G5: =+Mensual!H5 -> Nota | H5: =+Mensual!I5 -> Valor ponderado | I5: =+Mensual!J5 -> 0 | J5: =+Mensual!K5 -> 0.25 | K5: =+Mensual!L5 -> 0.5 | ... Q5: =+Mensual!R5 -> 0 | T5: Nota | U5: Nota
A6: =+Mensual!B6 -> 4 | B6: 0.3 | C6: 10. CONMOXA | D6: =IF(VLOOKUP($C6,Mensual!$D$6:$G$163,2,0)<0,0,VLOOKUP($C6,Mensual!$D$6:$G$163,2,0)) -> RESULTADO SCORECARD | E6: =IF(VLOOKUP($C6,Mensual!$D$6:$G$163,3,0)<0,0,VLOOKUP($C6,Mensual!$D$6:$G$163,3,0)) -> 1 | F6: =IF(VLOOKUP($C6,Mensual!$D$6:$G$163,4,0)<0,0,VLOOKUP($C6,Mensual!$D$6:$G$163,4,0)) -> 0.4255 | G6: =IF(VLOOKUP($C6,Mensual!$D$6:$H$163,5,0)<0,0,VLOOKUP($C6,Mensual!$D$6:$H$163,5,0)) -> 0.4255 | H6: =+G6*B6 -> 0.12765 | I6: =+Mensual!J6 -> 0 | J6: =+Mensual!K6 -> 0 | K6: =+Mensual!L6 -> 0 | L6: =+Mensual!M6 -> 0
B7: 0.3 | C7: 9. SCORE CARD Grupo EXA | D7: =IF(VLOOKUP($C7,Mensual!$D$6:$G$163,2,0)<0,0,VLOOKUP($C7,Mensual!$D$6:$G$163,2,0)) -> RESULTADO SCORECARD | E7: =IF(VLOOKUP($C7,Mensual!$D$6:$G$163,3,0)<0,0,VLOOKUP($C7,Mensual!$D$6:$G$163,3,0)) -> 1 | F7: =IF(VLOOKUP($C7,Mensual!$D$6:$G$163,4,0)<0,0,VLOOKUP($C7,Mensual!$D$6:$G$163,4,0)) -> 1.0325 | G7: =IF(VLOOKUP($C7,Mensual!$D$6:$H$163,5,0)<0,0,VLOOKUP($C7,Mensual!$D$6:$H$163,5,0)) -> 1.0325 | H7: =+G7*B7 -> 0.30975
B8: 0.1 | C8: 1.10 Aumentar ventas en articulos Sejue/get504 | D8: =IF(VLOOKUP($C8,Mensual!$D$6:$G$163,2,0)<0,0,VLOOKUP($C8,Mensual!$D$6:$G$163,2,0)) -> Articulos | E8: =IF(VLOOKUP($C8,Mensual!$D$6:$G$163,3,0)<0,0,VLOOKUP($C8,Mensual!$D$6:$G$163,3,0)) -> 10 | F8: =IF(VLOOKUP($C8,Mensual!$D$6:$G$163,4,0)<0,0,VLOOKUP($C8,Mensual!$D$6:$G$163,4,0)) -> 19 | G8: =IF(VLOOKUP($C8,Mensual!$D$6:$H$163,5,0)<0,0,VLOOKUP($C8,Mensual!$D$6:$H$163,5,0)) -> 1 | H8: =+G8*B8 -> 0.1
B9: 0.3 | C9: 1.5 Aumentar Rentas bienes y raices | D9: =IF(VLOOKUP($C9,Mensual!$D$6:$G$163,2,0)<0,0,VLOOKUP($C9,Mensual!$D$6:$G$163,2,0)) -> Porcentaje | E9: =IF(VLOOKUP($C9,Mensual!$D$6:$G$163,3,0)<0,0,VLOOKUP($C9,Mensual!$D$6:$G$163,3,0)) -> 0.2 | F9: =IF(VLOOKUP($C9,Mensual!$D$6:$G$163,4,0)<0,0,VLOOKUP($C9,Mensual!$D$6:$G$163,4,0)) -> 0 | G9: =IF(VLOOKUP($C9,Mensual!$D$6:$H$163,5,0)<0,0,VLOOKUP($C9,Mensual!$D$6:$H$163,5,0)) -> 0 | H9: =+G9*B9 -> 0
B10: =SUM(B6:B9) -> 1 | H10: =SUM(H6:H9) -> 0.5374

Sheet Roy Reyes
I1: 0.9
C2: Colaborador: | D2: Roy Reyes | I2: 80-90%
C3: Departamento: | D3: Contenedores | I3: Menos de 80%
A5: =+Mensual!B5 -> No | B5: =+Mensual!C5 -> Peso | D5: =+Mensual!E5 -> Unidad de medición | E5: =+Mensual!F5 -> Meta | F5: =+Mensual!G5 -> Resultado | G5: =+Mensual!H5 -> Nota | H5: =+Mensual!I5 -> Valor ponderado | I5: =+Mensual!J5 -> 0 | J5: =+Mensual!K5 -> 0.25 | K5: =+Mensual!L5 -> 0.5 | ... Q5: =+Mensual!R5 -> 0 | T5: Nota | U5: Nota
A6: =+Mensual!B6 -> 4 | B6: 0.4 | C6: 10. CONMOXA | D6: =IF(VLOOKUP($C6,Mensual!$D$6:$G$163,2,0)<0,0,VLOOKUP($C6,Mensual!$D$6:$G$163,2,0)) -> RESULTADO SCORECARD | E6: =IF(VLOOKUP($C6,Mensual!$D$6:$G$163,3,0)<0,0,VLOOKUP($C6,Mensual!$D$6:$G$163,3,0)) -> 1 | F6: =IF(VLOOKUP($C6,Mensual!$D$6:$G$163,4,0)<0,0,VLOOKUP($C6,Mensual!$D$6:$G$163,4,0)) -> 0.4255 | G6: =IF(VLOOKUP($C6,Mensual!$D$6:$H$163,5,0)<0,0,VLOOKUP($C6,Mensual!$D$6:$H$163,5,0)) -> 0.4255 | H6: =+G6*B6 -> 0.1702 | I6: =+Mensual!J6 -> 0 | J6: =+Mensual!K6 -> 0 | K6: =+Mensual!L6 -> 0 | L6: =+Mensual!M6 -> 0
B7: 0.1 | C7: 9. SCORE CARD Grupo EXA | D7: =IF(VLOOKUP($C7,Mensual!$D$6:$G$135,2,0)<0,0,VLOOKUP($C7,Mensual!$D$6:$G$135,2,0)) -> RESULTADO SCORECARD | E7: =IF(VLOOKUP($C7,Mensual!$D$6:$G$163,3,0)<0,0,VLOOKUP($C7,Mensual!$D$6:$G$163,3,0)) -> 1 | F7: =IF(VLOOKUP($C7,Mensual!$D$6:$G$163,4,0)<0,0,VLOOKUP($C7,Mensual!$D$6:$G$163,4,0)) -> 1.0325 | G7: =IF(VLOOKUP($C7,Mensual!$D$6:$H$163,5,0)<0,0,VLOOKUP($C7,Mensual!$D$6:$H$163,5,0)) -> 1.0325 | H7: =+G7*B7 -> 0.10325
B8: 0.2 | C8: 1.9 Aumento en ventas de GPS a terceros (nuevos clientes) | E8: =IF(VLOOKUP($C8,Mensual!$D$6:$G$163,3,0)<0,0,VLOOKUP($C8,Mensual!$D$6:$G$163,3,0)) -> 10 | F8: =IF(VLOOKUP($C8,Mensual!$D$6:$G$163,4,0)<0,0,VLOOKUP($C8,Mensual!$D$6:$G$163,4,0)) -> 0 | G8: =IF(VLOOKUP($C8,Mensual!$D$6:$H$163,5,0)<0,0,VLOOKUP($C8,Mensual!$D$6:$H$163,5,0)) -> 0 | H8: =+G8*B8 -> 0
B9: 0.3 | C9: 5.11 # de fallas operativas adjudicables al predio (Incluye rescates, rechazos) Puerto Cortes | D9: =IF(VLOOKUP($C9,Mensual!$D$6:$G$135,2,0)<0,0,VLOOKUP($C9,Mensual!$D$6:$G$135,2,0)) -> # de fallas | E9: =IF(VLOOKUP($C9,Mensual!$D$6:$G$163,3,0)<0,0,VLOOKUP($C9,Mensual!$D$6:$G$163,3,0)) -> 1 | F9: =IF(VLOOKUP($C9,Mensual!$D$6:$G$163,4,0)<0,0,VLOOKUP($C9,Mensual!$D$6:$G$163,4,0)) -> 0 | G9: =IF(VLOOKUP($C9,Mensual!$D$6:$H$163,5,0)<0,0,VLOOKUP($C9,Mensual!$D$6:$H$163,5,0)) -> 1 | H9: =+G9*B9 -> 0.3
B10: =SUM(B6:B9) -> 1 | H10: =SUM(H6:H9) -> 0.57345
C24: Agregar aprovechaimiento de gps. Mas que ventas y margen.
C25: Reemplazar el del margen.

Sheet TRANEXPA
I1: 0.9
C2: Departamento: | D2: Transporte | I2: 80-90%
I3: Menos de 80%
A5: =+Mensual!B5 -> No | B5: =+Mensual!C5 -> Peso | D5: =+Mensual!E5 -> Unidad de medición | E5: =+Mensual!F5 -> Meta | F5: =+Mensual!G5 -> Resultado | G5: =+Mensual!H5 -> Nota | H5: =+Mensual!I5 -> Valor ponderado | I5: =+Mensual!J5 -> 0 | J5: =+Mensual!K5 -> 0.25 | K5: =+Mensual!L5 -> 0.5 | ... Q5: =+Mensual!R5 -> 0 | T5: Nota | U5: Nota
A6: =+Mensual!B6 -> 4 | B6: 0.35 | C6: 9. SCORE CARD Grupo EXA | D6: =IF(VLOOKUP($C6,Mensual!$D$6:$G$163,2,0)<0,0,VLOOKUP($C6,Mensual!$D$6:$G$163,2,0)) -> RESULTADO SCORECARD | E6: =IF(VLOOKUP($C6,Mensual!$D$6:$G$163,3,0)<0,0,VLOOKUP($C6,Mensual!$D$6:$G$163,3,0)) -> 1 | F6: =IF(VLOOKUP($C6,Mensual!$D$6:$G$163,4,0)<0,0,VLOOKUP($C6,Mensual!$D$6:$G$163,4,0)) -> 1.0325 | G6: =IF(VLOOKUP($C6,Mensual!$D$6:$H$163,5,0)<0,0,VLOOKUP($C6,Mensual!$D$6:$H$163,5,0)) -> 1.0325 | H6: =+G6*B6 -> 0.361375 | I6: =+Mensual!J6 -> 0 | J6: =+Mensual!K6 -> 0 | K6: =+Mensual!L6 -> 0 | L6: =+Mensual!M6 -> 0
B7: 0.1 | C7: 2.17 Reducir costo por km/cabezal TRANEXPA | D7: =IF(VLOOKUP($C7,Mensual!$D$6:$G$163,2,0)<0,0,VLOOKUP($C7,Mensual!$D$6:$G$163,2,0)) -> 0 | E7: =IF(VLOOKUP($C7,Mensual!$D$6:$G$163,3,0)<0,0,VLOOKUP($C7,Mensual!$D$6:$G$163,3,0)) -> 0 | F7: =IF(VLOOKUP($C7,Mensual!$D$6:$G$163,4,0)<0,0,VLOOKUP($C7,Mensual!$D$6:$G$163,4,0)) -> 0.14 | G7: =IF(VLOOKUP($C7,Mensual!$D$6:$H$163,5,0)<0,0,VLOOKUP($C7,Mensual!$D$6:$H$163,5,0)) -> 0 | H7: =+G7*B7 -> 0
B8: 0.1 | C8: 3. Cero incidentes mayores de seguridad y sostenibilidad | D8: =IF(VLOOKUP($C8,Mensual!$D$6:$G$163,2,0)<0,0,VLOOKUP($C8,Mensual!$D$6:$G$163,2,0)) -> 0 | E8: =IF(VLOOKUP($C8,Mensual!$D$6:$G$163,3,0)<0,0,VLOOKUP($C8,Mensual!$D$6:$G$163,3,0)) -> 1 | F8: =IF(VLOOKUP($C8,Mensual!$D$6:$G$163,4,0)<0,0,VLOOKUP($C8,Mensual!$D$6:$G$163,4,0)) -> 1 | G8: =IF(VLOOKUP($C8,Mensual!$D$6:$H$163,5,0)<0,0,VLOOKUP($C8,Mensual!$D$6:$H$163,5,0)) -> 1 | H8: =+G8*B8 -> 0.1
B9: 0.1 | C9: 3.7 Cero accidente mayores Y/O robos TRANEXPA | D9: =IF(VLOOKUP($C9,Mensual!$D$6:$G$163,2,0)<0,0,VLOOKUP($C9,Mensual!$D$6:$G$163,2,0)) -> 0 | E9: =IF(VLOOKUP($C9,Mensual!$D$6:$G$163,3,0)<0,0,VLOOKUP($C9,Mensual!$D$6:$G$163,3,0)) -> 0 | F9: =IF(VLOOKUP($C9,Mensual!$D$6:$G$163,4,0)<0,0,VLOOKUP($C9,Mensual!$D$6:$G$163,4,0)) -> 0 | G9: =IF(VLOOKUP($C9,Mensual!$D$6:$H$163,5,0)<0,0,VLOOKUP($C9,Mensual!$D$6:$H$163,5,0)) -> 0 | H9: =+G9*B9 -> 0
B10: 0.1 | C10: 5.10 Aumentar kms TRANEXPA | D10: =IF(VLOOKUP($C10,Mensual!$D$6:$G$163,2,0)<0,0,VLOOKUP($C10,Mensual!$D$6:$G$163,2,0)) -> kms | E10: =IF(VLOOKUP($C10,Mensual!$D$6:$G$163,3,0)<0,0,VLOOKUP($C10,Mensual!$D$6:$G$163,3,0)) -> 0.2 | F10: =IF(VLOOKUP($C10,Mensual!$D$6:$G$163,4,0)<0,0,VLOOKUP($C10,Mensual!$D$6:$G$163,4,0)) -> 0 | G10: =IF(VLOOKUP($C10,Mensual!$D$6:$H$163,5,0)<0,0,VLOOKUP($C10,Mensual!$D$6:$H$163,5,0)) -> 0 | H10: =+G10*B10 -> 0
B11: 0.1 | C11: 5.3 Productividad cabezales TRANEXPA | D11: =IF(VLOOKUP($C11,Mensual!$D$6:$G$163,2,0)<0,0,VLOOKUP($C11,Mensual!$D$6:$G$163,2,0)) -> 0 | E11: =IF(VLOOKUP($C11,Mensual!$D$6:$G$163,3,0)<0,0,VLOOKUP($C11,Mensual!$D$6:$G$163,3,0)) -> 4000 | F11: =IF(VLOOKUP($C11,Mensual!$D$6:$G$163,4,0)<0,0,VLOOKUP($C11,Mensual!$D$6:$G$163,4,0)) -> 4268 | G11: =IF(VLOOKUP($C11,Mensual!$D$6:$H$163,5,0)<0,0,VLOOKUP($C11,Mensual!$D$6:$H$163,5,0)) -> 1 | H11: =+G11*B11 -> 0.1
B12: 0.05 | C12: 6.5 Disminuir a 0-1 el desuso de cabezales propios | D12: =IF(VLOOKUP($C12,Mensual!$D$6:$G$163,2,0)<0,0,VLOOKUP($C12,Mensual!$D$6:$G$163,2,0)) -> cabezal | E12: =IF(VLOOKUP($C12,Mensual!$D$6:$G$163,3,0)<0,0,VLOOKUP($C12,Mensual!$D$6:$G$163,3,0)) -> 1 | F12: =IF(VLOOKUP($C12,Mensual!$D$6:$G$163,4,0)<0,0,VLOOKUP($C12,Mensual!$D$6:$G$163,4,0)) -> 1 | G12: =IF(VLOOKUP($C12,Mensual!$D$6:$H$163,5,0)<0,0,VLOOKUP($C12,Mensual!$D$6:$H$163,5,0)) -> 0 | H12: =+G12*B12 -> 0
B13: 0.1 | C13: 2.3 Reducir Costo por km cabezales propios. | D13: =IF(VLOOKUP($C13,Mensual!$D$6:$G$163,2,0)<0,0,VLOOKUP($C13,Mensual!$D$6:$G$163,2,0)) -> $ | E13: =IF(VLOOKUP($C13,Mensual!$D$6:$G$163,3,0)<0,0,VLOOKUP($C13,Mensual!$D$6:$G$163,3,0)) -> 0.05 | F13: =IF(VLOOKUP($C13,Mensual!$D$6:$G$163,4,0)<0,0,VLOOKUP($C13,Mensual!$D$6:$G$163,4,0)) -> 0.6 | G13: =IF(VLOOKUP($C13,Mensual!$D$6:$H$163,5,0)<0,0,VLOOKUP($C13,Mensual!$D$6:$H$163,5,0)) -> 1 | H13: =+G13*B13 -> 0.1
B14: =SUM(B6:B13) -> 1 | H14: =SUM(H6:H13) -> 0.661375
C18: Colaboradores:

Sheet TREXA
I1: 0.9
C2: Departamento: | D2: Administracion | I2: 80-90%
I3: Menos de 80%
A5: =+Mensual!B5 -> No | B5: =+Mensual!C5 -> Peso | D5: =+Mensual!E5 -> Unidad de medición | E5: =+Mensual!F5 -> Meta | F5: =+Mensual!G5 -> Resultado | G5: =+Mensual!H5 -> Nota | H5: =+Mensual!I5 -> Valor ponderado | I5: =+Mensual!J5 -> 0 | J5: =+Mensual!K5 -> 0.25 | K5: =+Mensual!L5 -> 0.5 | ... Q5: =+Mensual!R5 -> 0 | T5: Nota | U5: Nota
A6: =+Mensual!B6 -> 4 | B6: 0.25 | C6: 9. SCORE CARD Grupo EXA | D6: =IF(VLOOKUP($C6,Mensual!$D$6:$G$163,2,0)<0,0,VLOOKUP($C6,Mensual!$D$6:$G$163,2,0)) -> RESULTADO SCORECARD | E6: =IF(VLOOKUP($C6,Mensual!$D$6:$G$163,3,0)<0,0,VLOOKUP($C6,Mensual!$D$6:$G$163,3,0)) -> 1 | F6: =IF(VLOOKUP($C6,Mensual!$D$6:$G$163,4,0)<0,0,VLOOKUP($C6,Mensual!$D$6:$G$163,4,0)) -> 1.0325 | G6: =IF(VLOOKUP($C6,Mensual!$D$6:$H$163,5,0)<0,0,VLOOKUP($C6,Mensual!$D$6:$H$163,5,0)) -> 1.0325 | H6: =+G6*B6 -> 0.258125 | I6: =+Mensual!J6 -> 0 | J6: =+Mensual!K6 -> 0 | K6: =+Mensual!L6 -> 0 | L6: =+Mensual!M6 -> 0
B7: 0.2 | C7: 2.22 Aumentar margen neto alquiler de contenedores secos (solo o en combo) TREXA | D7: =IF(VLOOKUP($C7,Mensual!$D$6:$G$163,2,0)<0,0,VLOOKUP($C7,Mensual!$D$6:$G$163,2,0)) -> 0 | E7: =IF(VLOOKUP($C7,Mensual!$D$6:$G$163,3,0)<0,0,VLOOKUP($C7,Mensual!$D$6:$G$163,3,0)) -> 0.1 | F7: =IF(VLOOKUP($C7,Mensual!$D$6:$G$163,4,0)<0,0,VLOOKUP($C7,Mensual!$D$6:$G$163,4,0)) -> 0.1 | G7: =IF(VLOOKUP($C7,Mensual!$D$6:$H$163,5,0)<0,0,VLOOKUP($C7,Mensual!$D$6:$H$163,5,0)) -> 1 | H7: =+G7*B7 -> 0.2
B8: 0.2 | C8: 1.17 Aumentar el numero de cliente semestralmente | D8: =IF(VLOOKUP($C8,Mensual!$D$6:$G$163,2,0)<0,0,VLOOKUP($C8,Mensual!$D$6:$G$163,2,0)) -> cliente | E8: =IF(VLOOKUP($C8,Mensual!$D$6:$G$163,3,0)<0,0,VLOOKUP($C8,Mensual!$D$6:$G$163,3,0)) -> 1 | F8: =IF(VLOOKUP($C8,Mensual!$D$6:$G$163,4,0)<0,0,VLOOKUP($C8,Mensual!$D$6:$G$163,4,0)) -> 0 | G8: =IF(VLOOKUP($C8,Mensual!$D$6:$H$163,5,0)<0,0,VLOOKUP($C8,Mensual!$D$6:$H$163,5,0)) -> 0 | H8: =+G8*B8 -> 0
B9: 0.1 | C9: 3.6.1 Cierre TREXA | D9: =IF(VLOOKUP($C9,Mensual!$D$6:$G$163,2,0)<0,0,VLOOKUP($C9,Mensual!$D$6:$G$163,2,0)) -> # de cierres a tiempo | E9: =IF(VLOOKUP($C9,Mensual!$D$6:$G$163,3,0)<0,0,VLOOKUP($C9,Mensual!$D$6:$G$163,3,0)) -> 1 | F9: =IF(VLOOKUP($C9,Mensual!$D$6:$G$163,4,0)<0,0,VLOOKUP($C9,Mensual!$D$6:$G$163,4,0)) -> 1 | G9: =IF(VLOOKUP($C9,Mensual!$D$6:$H$163,5,0)<0,0,VLOOKUP($C9,Mensual!$D$6:$H$163,5,0)) -> 1 | H9: =+G9*B9 -> 0.1
B10: 0.25 | C10: 1.8 Aumentar ventas en TREXA | D10: =IF(VLOOKUP($C10,Mensual!$D$6:$G$163,2,0)<0,0,VLOOKUP($C10,Mensual!$D$6:$G$163,2,0)) -> Dólares | E10: =IF(VLOOKUP($C10,Mensual!$D$6:$G$163,3,0)<0,0,VLOOKUP($C10,Mensual!$D$6:$G$163,3,0)) -> 0.2 | F10: =IF(VLOOKUP($C10,Mensual!$D$6:$G$163,4,0)<0,0,VLOOKUP($C10,Mensual!$D$6:$G$163,4,0)) -> 1.03 | G10: =IF(VLOOKUP($C10,Mensual!$D$6:$H$163,5,0)<0,0,VLOOKUP($C10,Mensual!$D$6:$H$163,5,0)) -> 1 | H10: =+G10*B10 -> 0.25
B11: =SUM(B6:B10) -> 1 | H11: =SUM(H6:H10) -> 0.808125
C14: Colaboradores:
C15: Tamara Castro

Sheet Julio - Alejandro
I1: 0.9
C2: Departamento: | D2: Administracion | I2: 80-90%
I3: Menos de 80%
A5: =+Mensual!B5 -> No | B5: =+Mensual!C5 -> Peso | D5: =+Mensual!E5 -> Unidad de medición | E5: =+Mensual!F5 -> Meta | F5: =+Mensual!G5 -> Resultado | G5: =+Mensual!H5 -> Nota | H5: =+Mensual!I5 -> Valor ponderado | I5: =+Mensual!J5 -> 0 | J5: =+Mensual!K5 -> 0.25 | K5: =+Mensual!L5 -> 0.5 | ... Q5: =+Mensual!R5 -> 0 | T5: Nota | U5: Nota
A6: =+Mensual!B6 -> 4 | B6: 0.3 | C6: 9. SCORE CARD Grupo EXA | D6: =IF(VLOOKUP($C6,Mensual!$D$6:$G$163,2,0)<0,0,VLOOKUP($C6,Mensual!$D$6:$G$163,2,0)) -> RESULTADO SCORECARD | E6: =IF(VLOOKUP($C6,Mensual!$D$6:$G$163,3,0)<0,0,VLOOKUP($C6,Mensual!$D$6:$G$163,3,0)) -> 1 | F6: =IF(VLOOKUP($C6,Mensual!$D$6:$G$163,4,0)<0,0,VLOOKUP($C6,Mensual!$D$6:$G$163,4,0)) -> 1.0325 | G6: =IF(VLOOKUP($C6,Mensual!$D$6:$H$163,5,0)<0,0,VLOOKUP($C6,Mensual!$D$6:$H$163,5,0)) -> 1.0325 | H6: =+G6*B6 -> 0.30975 | I6: =+Mensual!J6 -> 0 | J6: =+Mensual!K6 -> 0 | K6: =+Mensual!L6 -> 0 | L6: =+Mensual!M6 -> 0
B7: 0.1 | C7: 2.1 Reducir gasto administrativo x% | D7: =IF(VLOOKUP($C7,Mensual!$D$6:$G$163,2,0)<0,0,VLOOKUP($C7,Mensual!$D$6:$G$163,2,0)) -> % | E7: =IF(VLOOKUP($C7,Mensual!$D$6:$G$163,3,0)<0,0,VLOOKUP($C7,Mensual!$D$6:$G$163,3,0)) -> 0.1 | F7: =IF(VLOOKUP($C7,Mensual!$D$6:$G$163,4,0)<0,0,VLOOKUP($C7,Mensual!$D$6:$G$163,4,0)) -> 0.32 | G7: =IF(VLOOKUP($C7,Mensual!$D$6:$H$163,5,0)<0,0,VLOOKUP($C7,Mensual!$D$6:$H$163,5,0)) -> 1 | H7: =+G7*B7 -> 0.1
B8: 0.05 | C8: 3.5 Multas ambientales y fiscales. | D8: =IF(VLOOKUP($C8,Mensual!$D$6:$G$163,2,0)<0,0,VLOOKUP($C8,Mensual!$D$6:$G$163,2,0)) -> 0 | E8: =IF(VLOOKUP($C8,Mensual!$D$6:$G$163,3,0)<0,0,VLOOKUP($C8,Mensual!$D$6:$G$163,3,0)) -> 0 | F8: =IF(VLOOKUP($C8,Mensual!$D$6:$G$163,4,0)<0,0,VLOOKUP($C8,Mensual!$D$6:$G$163,4,0)) -> 0 | G8: =IF(VLOOKUP($C8,Mensual!$D$6:$H$163,5,0)<0,0,VLOOKUP($C8,Mensual!$D$6:$H$163,5,0)) -> 1 | H8: =+G8*B8 -> 0.05
B9: 0.05 | C9: 7. Disminuir el D/E | D9: =IF(VLOOKUP($C9,Mensual!$D$6:$G$163,2,0)<0,0,VLOOKUP($C9,Mensual!$D$6:$G$163,2,0)) -> 0 | E9: =IF(VLOOKUP($C9,Mensual!$D$6:$G$163,3,0)<0,0,VLOOKUP($C9,Mensual!$D$6:$G$163,3,0)) -> 0.05 | F9: =IF(VLOOKUP($C9,Mensual!$D$6:$G$163,4,0)<0,0,VLOOKUP($C9,Mensual!$D$6:$G$163,4,0)) -> 0.05 | G9: =IF(VLOOKUP($C9,Mensual!$D$6:$H$163,5,0)<0,0,VLOOKUP($C9,Mensual!$D$6:$H$163,5,0)) -> 1 | H9: =+G9*B9 -> 0.05
B10: 0.1 | C10: 6. Aumentar el ROA | D10: =IF(VLOOKUP($C10,Mensual!$D$6:$G$163,2,0)<0,0,VLOOKUP($C10,Mensual!$D$6:$G$163,2,0)) -> 0 | E10: =IF(VLOOKUP($C10,Mensual!$D$6:$G$163,3,0)<0,0,VLOOKUP($C10,Mensual!$D$6:$G$163,3,0)) -> 0.05 | F10: =IF(VLOOKUP($C10,Mensual!$D$6:$G$163,4,0)<0,0,VLOOKUP($C10,Mensual!$D$6:$G$163,4,0)) -> 1 | G10: =IF(VLOOKUP($C10,Mensual!$D$6:$H$163,5,0)<0,0,VLOOKUP($C10,Mensual!$D$6:$H$163,5,0)) -> 1 | H10: =+G10*B10 -> 0.1
B11: 0.1 | C11: 3.6 Cierres contables a mas tardar el 6 de cada mes | D11: =IF(VLOOKUP($C11,Mensual!$D$6:$G$163,2,0)<0,0,VLOOKUP($C11,Mensual!$D$6:$G$163,2,0)) -> # de cierres a tiempo | E11: =IF(VLOOKUP($C11,Mensual!$D$6:$G$163,3,0)<0,0,VLOOKUP($C11,Mensual!$D$6:$G$163,3,0)) -> 6 | F11: =IF(VLOOKUP($C11,Mensual!$D$6:$G$163,4,0)<0,0,VLOOKUP($C11,Mensual!$D$6:$G$163,4,0)) -> 6 | G11: =IF(VLOOKUP($C11,Mensual!$D$6:$H$163,5,0)<0,0,VLOOKUP($C11,Mensual!$D$6:$H$163,5,0)) -> 1 | H11: =+G11*B11 -> 0.1
B12: 0.1 | C12: 6.2 Disminuir a 5% el desuso de los chasis (equipos con mas de 30 dias en las yardas) | D12: =IF(VLOOKUP($C12,Mensual!$D$6:$G$163,2,0)<0,0,VLOOKUP($C12,Mensual!$D$6:$G$163,2,0)) -> % | E12: =IF(VLOOKUP($C12,Mensual!$D$6:$G$163,3,0)<0,0,VLOOKUP($C12,Mensual!$D$6:$G$163,3,0)) -> 0.05 | F12: =IF(VLOOKUP($C12,Mensual!$D$6:$G$163,4,0)<0,0,VLOOKUP($C12,Mensual!$D$6:$G$163,4,0)) -> 0.05 | G12: =IF(VLOOKUP($C12,Mensual!$D$6:$H$163,5,0)<0,0,VLOOKUP($C12,Mensual!$D$6:$H$163,5,0)) -> 1 | H12: =+G12*B12 -> 0.1
B13: 0.1 | C13: 7.1 Rotación de cuentas por cobrar. | D13: =IF(VLOOKUP($C13,Mensual!$D$6:$G$163,2,0)<0,0,VLOOKUP($C13,Mensual!$D$6:$G$163,2,0)) -> 0 | E13: =IF(VLOOKUP($C13,Mensual!$D$6:$G$163,3,0)<0,0,VLOOKUP($C13,Mensual!$D$6:$G$163,3,0)) -> 0.1 | F13: =IF(VLOOKUP($C13,Mensual!$D$6:$G$163,4,0)<0,0,VLOOKUP($C13,Mensual!$D$6:$G$163,4,0)) -> 0 | G13: =IF(VLOOKUP($C13,Mensual!$D$6:$H$163,5,0)<0,0,VLOOKUP($C13,Mensual!$D$6:$H$163,5,0)) -> 0 | H13: =+G13*B13 -> 0
B14: 0.1 | C14: 5.16 # de notas de credito mensuales | D14: =IF(VLOOKUP($C14,Mensual!$D$6:$G$163,2,0)<0,0,VLOOKUP($C14,Mensual!$D$6:$G$163,2,0)) -> # notas de credito | E14: =IF(VLOOKUP($C14,Mensual!$D$6:$G$163,3,0)<0,0,VLOOKUP($C14,Mensual!$D$6:$G$163,3,0)) -> 0 | F14: =IF(VLOOKUP($C14,Mensual!$D$6:$G$163,4,0)<0,0,VLOOKUP($C14,Mensual!$D$6:$G$163,4,0)) -> 0 | G14: =IF(VLOOKUP($C14,Mensual!$D$6:$H$163,5,0)<0,0,VLOOKUP($C14,Mensual!$D$6:$H$163,5,0)) -> 0 | H14: =+G14*B14 -> 0
B15: =SUM(B6:B14) -> 1 | H15: =SUM(H6:H14) -> 0.80975
C18: Colaboradores:
C19: Alejandro Garcia
C20: Julio Estevez

Sheet Cecilia
I1: 0.9
C2: Departamento: | D2: Administracion | I2: 80-90%
I3: Menos de 80%
A5: =+Mensual!B5 -> No | B5: =+Mensual!C5 -> Peso | D5: =+Mensual!E5 -> Unidad de medición | E5: =+Mensual!F5 -> Meta | F5: =+Mensual!G5 -> Resultado | G5: =+Mensual!H5 -> Nota | H5: =+Mensual!I5 -> Valor ponderado | I5: =+Mensual!J5 -> 0 | J5: =+Mensual!K5 -> 0.25 | K5: =+Mensual!L5 -> 0.5 | ... Q5: =+Mensual!R5 -> 0 | T5: Nota | U5: Nota
A6: =+Mensual!B6 -> 4 | B6: 0.25 | C6: 9. SCORE CARD Grupo EXA | D6: =IF(VLOOKUP($C6,Mensual!$D$6:$G$163,2,0)<0,0,VLOOKUP($C6,Mensual!$D$6:$G$163,2,0)) -> RESULTADO SCORECARD | E6: =IF(VLOOKUP($C6,Mensual!$D$6:$G$163,3,0)<0,0,VLOOKUP($C6,Mensual!$D$6:$G$163,3,0)) -> 1 | F6: =IF(VLOOKUP($C6,Mensual!$D$6:$G$163,4,0)<0,0,VLOOKUP($C6,Mensual!$D$6:$G$163,4,0)) -> 1.0325 | G6: =IF(VLOOKUP($C6,Mensual!$D$6:$H$163,5,0)<0,0,VLOOKUP($C6,Mensual!$D$6:$H$163,5,0)) -> 1.0325 | H6: =+G6*B6 -> 0.258125 | I6: =+Mensual!J6 -> 0 | J6: =+Mensual!K6 -> 0 | K6: =+Mensual!L6 -> 0 | L6: =+Mensual!M6 -> 0
B7: 0.05 | C7: 2.1 Reducir gasto administrativo x% | D7: =IF(VLOOKUP($C7,Mensual!$D$6:$G$163,2,0)<0,0,VLOOKUP($C7,Mensual!$D$6:$G$163,2,0)) -> % | E7: =IF(VLOOKUP($C7,Mensual!$D$6:$G$163,3,0)<0,0,VLOOKUP($C7,Mensual!$D$6:$G$163,3,0)) -> 0.1 | F7: =IF(VLOOKUP($C7,Mensual!$D$6:$G$163,4,0)<0,0,VLOOKUP($C7,Mensual!$D$6:$G$163,4,0)) -> 0.32 | G7: =IF(VLOOKUP($C7,Mensual!$D$6:$H$163,5,0)<0,0,VLOOKUP($C7,Mensual!$D$6:$H$163,5,0)) -> 1 | H7: =+G7*B7 -> 0.05
B8: 0.05 | C8: 6.1 Aumentar Rotación de inventario. | D8: =IF(VLOOKUP($C8,Mensual!$D$6:$G$163,2,0)<0,0,VLOOKUP($C8,Mensual!$D$6:$G$163,2,0)) -> 0 | E8: =IF(VLOOKUP($C8,Mensual!$D$6:$G$163,3,0)<0,0,VLOOKUP($C8,Mensual!$D$6:$G$163,3,0)) -> 0.05 | F8: =IF(VLOOKUP($C8,Mensual!$D$6:$G$163,4,0)<0,0,VLOOKUP($C8,Mensual!$D$6:$G$163,4,0)) -> 0 | G8: =IF(VLOOKUP($C8,Mensual!$D$6:$H$163,5,0)<0,0,VLOOKUP($C8,Mensual!$D$6:$H$163,5,0)) -> 0 | H8: =+G8*B8 -> 0
B9: 0.2 | C9: 2.3 Reducir Costo por km cabezales propios. | D9: =IF(VLOOKUP($C9,Mensual!$D$6:$G$163,2,0)<0,0,VLOOKUP($C9,Mensual!$D$6:$G$163,2,0)) -> $ | E9: =IF(VLOOKUP($C9,Mensual!$D$6:$G$163,3,0)<0,0,VLOOKUP($C9,Mensual!$D$6:$G$163,3,0)) -> 0.05 | F9: =IF(VLOOKUP($C9,Mensual!$D$6:$G$163,4,0)<0,0,VLOOKUP($C9,Mensual!$D$6:$G$163,4,0)) -> 0.6 | G9: =IF(VLOOKUP($C9,Mensual!$D$6:$H$163,5,0)<0,0,VLOOKUP($C9,Mensual!$D$6:$H$163,5,0)) -> 1 | H9: =+G9*B9 -> 0.2
B10: 0.2 | C10: 5.2 Productividad cabezales Flota Nueva | D10: =IF(VLOOKUP($C10,Mensual!$D$6:$G$163,2,0)<0,0,VLOOKUP($C10,Mensual!$D$6:$G$163,2,0)) -> 0 | E10: =IF(VLOOKUP($C10,Mensual!$D$6:$G$163,3,0)<0,0,VLOOKUP($C10,Mensual!$D$6:$G$163,3,0)) -> 4500 | F10: =IF(VLOOKUP($C10,Mensual!$D$6:$G$163,4,0)<0,0,VLOOKUP($C10,Mensual!$D$6:$G$163,4,0)) -> 4782 | G10: =IF(VLOOKUP($C10,Mensual!$D$6:$H$163,5,0)<0,0,VLOOKUP($C10,Mensual!$D$6:$H$163,5,0)) -> 1 | H10: =+G10*B10 -> 0.2
B11: 0.1 | C11: 6.5 Disminuir a 0-1 el desuso de cabezales propios | D11: =IF(VLOOKUP($C11,Mensual!$D$6:$G$163,2,0)<0,0,VLOOKUP($C11,Mensual!$D$6:$G$163,2,0)) -> cabezal | E11: =IF(VLOOKUP($C11,Mensual!$D$6:$G$163,3,0)<0,0,VLOOKUP($C11,Mensual!$D$6:$G$163,3,0)) -> 1 | F11: =IF(VLOOKUP($C11,Mensual!$D$6:$G$163,4,0)<0,0,VLOOKUP($C11,Mensual!$D$6:$G$163,4,0)) -> 1 | G11: =IF(VLOOKUP($C11,Mensual!$D$6:$H$163,5,0)<0,0,VLOOKUP($C11,Mensual!$D$6:$H$163,5,0)) -> 0 | H11: =+G11*B11 -> 0
B12: 0.05 | C12: 7. Disminuir el D/E | D12: =IF(VLOOKUP($C12,Mensual!$D$6:$G$163,2,0)<0,0,VLOOKUP($C12,Mensual!$D$6:$G$163,2,0)) -> 0 | E12: =IF(VLOOKUP($C12,Mensual!$D$6:$G$163,3,0)<0,0,VLOOKUP($C12,Mensual!$D$6:$G$163,3,0)) -> 0.05 | F12: =IF(VLOOKUP($C12,Mensual!$D$6:$G$163,4,0)<0,0,VLOOKUP($C12,Mensual!$D$6:$G$163,4,0)) -> 0.05 | G12: =IF(VLOOKUP($C12,Mensual!$D$6:$H$163,5,0)<0,0,VLOOKUP($C12,Mensual!$D$6:$H$163,5,0)) -> 1 | H12: =+G12*B12 -> 0.05
B13: 0.05 | C13: 6. Aumentar el ROA | D13: =IF(VLOOKUP($C13,Mensual!$D$6:$G$163,2,0)<0,0,VLOOKUP($C13,Mensual!$D$6:$G$163,2,0)) -> 0 | E13: =IF(VLOOKUP($C13,Mensual!$D$6:$G$163,3,0)<0,0,VLOOKUP($C13,Mensual!$D$6:$G$163,3,0)) -> 0.05 | F13: =IF(VLOOKUP($C13,Mensual!$D$6:$G$163,4,0)<0,0,VLOOKUP($C13,Mensual!$D$6:$G$163,4,0)) -> 1 | G13: =IF(VLOOKUP($C13,Mensual!$D$6:$H$163,5,0)<0,0,VLOOKUP($C13,Mensual!$D$6:$H$163,5,0)) -> 1 | H13: =+G13*B13 -> 0.05
B14: 0.05 | C14: 3.6 Cierres contables a mas tardar el 6 de cada mes | D14: =IF(VLOOKUP($C14,Mensual!$D$6:$G$163,2,0)<0,0,VLOOKUP($C14,Mensual!$D$6:$G$163,2,0)) -> # de cierres a tiempo | E14: =IF(VLOOKUP($C14,Mensual!$D$6:$G$163,3,0)<0,0,VLOOKUP($C14,Mensual!$D$6:$G$163,3,0)) -> 6 | F14: =IF(VLOOKUP($C14,Mensual!$D$6:$G$163,4,0)<0,0,VLOOKUP($C14,Mensual!$D$6:$G$163,4,0)) -> 6 | G14: =IF(VLOOKUP($C14,Mensual!$D$6:$H$163,5,0)<0,0,VLOOKUP($C14,Mensual!$D$6:$H$163,5,0)) -> 1 | H14: =+G14*B14 -> 0.05
B15: =SUM(B6:B14) -> 1 | H15: =SUM(H6:H14) -> 0.858125
C18: Colaboradores:
C19: Cecilia Galeano

Sheet Compras
I1: 0.9
C2: Departamento: | D2: Administracion | I2: 80-90%
I3: Menos de 80%
A5: =+Mensual!B5 -> No | B5: =+Mensual!C5 -> Peso | D5: =+Mensual!E5 -> Unidad de medición | E5: =+Mensual!F5 -> Meta | F5: =+Mensual!G5 -> Resultado | G5: =+Mensual!H5 -> Nota | H5: =+Mensual!I5 -> Valor ponderado | I5: =+Mensual!J5 -> 0 | J5: =+Mensual!K5 -> 0.25 | K5: =+Mensual!L5 -> 0.5 | ... Q5: =+Mensual!R5 -> 0 | T5: Nota | U5: Nota
A6: =+Mensual!B6 -> 4 | B6: 0.25 | C6: 9. SCORE CARD Grupo EXA | D6: =IF(VLOOKUP($C6,Mensual!$D$6:$G$163,2,0)<0,0,VLOOKUP($C6,Mensual!$D$6:$G$163,2,0)) -> RESULTADO SCORECARD | E6: =IF(VLOOKUP($C6,Mensual!$D$6:$G$163,3,0)<0,0,VLOOKUP($C6,Mensual!$D$6:$G$163,3,0)) -> 1 | F6: =IF(VLOOKUP($C6,Mensual!$D$6:$G$163,4,0)<0,0,VLOOKUP($C6,Mensual!$D$6:$G$163,4,0)) -> 1.0325 | G6: =IF(VLOOKUP($C6,Mensual!$D$6:$H$163,5,0)<0,0,VLOOKUP($C6,Mensual!$D$6:$H$163,5,0)) -> 1.0325 | H6: =+G6*B6 -> 0.258125 | I6: =+Mensual!J6 -> 0 | J6: =+Mensual!K6 -> 0 | K6: =+Mensual!L6 -> 0 | L6: =+Mensual!M6 -> 0
B7: 0.1 | C7: 2.1 Reducir gasto administrativo x% | D7: =IF(VLOOKUP($C7,Mensual!$D$6:$G$163,2,0)<0,0,VLOOKUP($C7,Mensual!$D$6:$G$163,2,0)) -> % | E7: =IF(VLOOKUP($C7,Mensual!$D$6:$G$163,3,0)<0,0,VLOOKUP($C7,Mensual!$D$6:$G$163,3,0)) -> 0.1 | F7: =IF(VLOOKUP($C7,Mensual!$D$6:$G$163,4,0)<0,0,VLOOKUP($C7,Mensual!$D$6:$G$163,4,0)) -> 0.32 | G7: =IF(VLOOKUP($C7,Mensual!$D$6:$H$163,5,0)<0,0,VLOOKUP($C7,Mensual!$D$6:$H$163,5,0)) -> 1 | H7: =+G7*B7 -> 0.1
B8: 0.2 | C8: 6.1 Aumentar Rotación de inventario. | D8: =IF(VLOOKUP($C8,Mensual!$D$6:$G$163,2,0)<0,0,VLOOKUP($C8,Mensual!$D$6:$G$163,2,0)) -> 0 | E8: =IF(VLOOKUP($C8,Mensual!$D$6:$G$163,3,0)<0,0,VLOOKUP($C8,Mensual!$D$6:$G$163,3,0)) -> 0.05 | F8: =IF(VLOOKUP($C8,Mensual!$D$6:$G$163,4,0)<0,0,VLOOKUP($C8,Mensual!$D$6:$G$163,4,0)) -> 0 | G8: =IF(VLOOKUP($C8,Mensual!$D$6:$H$163,5,0)<0,0,VLOOKUP($C8,Mensual!$D$6:$H$163,5,0)) -> 0 | H8: =+G8*B8 -> 0
B9: 0.1 | C9: 2.3 Reducir Costo por km cabezales propios. | D9: =IF(VLOOKUP($C9,Mensual!$D$6:$G$163,2,0)<0,0,VLOOKUP($C9,Mensual!$D$6:$G$163,2,0)) -> $ | E9: =IF(VLOOKUP($C9,Mensual!$D$6:$G$163,3,0)<0,0,VLOOKUP($C9,Mensual!$D$6:$G$163,3,0)) -> 0.05 | F9: =IF(VLOOKUP($C9,Mensual!$D$6:$G$163,4,0)<0,0,VLOOKUP($C9,Mensual!$D$6:$G$163,4,0)) -> 0.6 | G9: =IF(VLOOKUP($C9,Mensual!$D$6:$H$163,5,0)<0,0,VLOOKUP($C9,Mensual!$D$6:$H$163,5,0)) -> 1 | H9: =+G9*B9 -> 0.1
B10: 0.05 | C10: 5.2 Productividad cabezales Flota Nueva | D10: =IF(VLOOKUP($C10,Mensual!$D$6:$G$163,2,0)<0,0,VLOOKUP($C10,Mensual!$D$6:$G$163,2,0)) -> 0 | E10: =IF(VLOOKUP($C10,Mensual!$D$6:$G$163,3,0)<0,0,VLOOKUP($C10,Mensual!$D$6:$G$163,3,0)) -> 4500 | F10: =IF(VLOOKUP($C10,Mensual!$D$6:$G$163,4,0)<0,0,VLOOKUP($C10,Mensual!$D$6:$G$163,4,0)) -> 4782 | G10: =IF(VLOOKUP($C10,Mensual!$D$6:$H$163,5,0)<0,0,VLOOKUP($C10,Mensual!$D$6:$H$163,5,0)) -> 1 | H10: =+G10*B10 -> 0.05
B11: 0.05 | C11: 6.5 Disminuir a 0-1 el desuso de cabezales propios | D11: =IF(VLOOKUP($C11,Mensual!$D$6:$G$163,2,0)<0,0,VLOOKUP($C11,Mensual!$D$6:$G$163,2,0)) -> cabezal | E11: =IF(VLOOKUP($C11,Mensual!$D$6:$G$163,3,0)<0,0,VLOOKUP($C11,Mensual!$D$6:$G$163,3,0)) -> 1 | F11: =IF(VLOOKUP($C11,Mensual!$D$6:$G$163,4,0)<0,0,VLOOKUP($C11,Mensual!$D$6:$G$163,4,0)) -> 1 | G11: =IF(VLOOKUP($C11,Mensual!$D$6:$H$163,5,0)<0,0,VLOOKUP($C11,Mensual!$D$6:$H$163,5,0)) -> 0 | H11: =+G11*B11 -> 0
B12: 0.025 | C12: 7. Disminuir el D/E | D12: =IF(VLOOKUP($C12,Mensual!$D$6:$G$163,2,0)<0,0,VLOOKUP($C12,Mensual!$D$6:$G$163,2,0)) -> 0 | E12: =IF(VLOOKUP($C12,Mensual!$D$6:$G$163,3,0)<0,0,VLOOKUP($C12,Mensual!$D$6:$G$163,3,0)) -> 0.05 | F12: =IF(VLOOKUP($C12,Mensual!$D$6:$G$163,4,0)<0,0,VLOOKUP($C12,Mensual!$D$6:$G$163,4,0)) -> 0.05 | G12: =IF(VLOOKUP($C12,Mensual!$D$6:$H$163,5,0)<0,0,VLOOKUP($C12,Mensual!$D$6:$H$163,5,0)) -> 1 | H12: =+G12*B12 -> 0.025
B13: 0.1 | C13: 2.2 Reducir costo de M&R de chasis propios | D13: =IF(VLOOKUP($C13,Mensual!$D$6:$G$163,2,0)<0,0,VLOOKUP($C13,Mensual!$D$6:$G$163,2,0)) -> $/km | E13: =IF(VLOOKUP($C13,Mensual!$D$6:$G$163,3,0)<0,0,VLOOKUP($C13,Mensual!$D$6:$G$163,3,0)) -> 0.05 | F13: =IF(VLOOKUP($C13,Mensual!$D$6:$G$163,4,0)<0,0,VLOOKUP($C13,Mensual!$D$6:$G$163,4,0)) -> 0.09 | G13: =IF(VLOOKUP($C13,Mensual!$D$6:$H$163,5,0)<0,0,VLOOKUP($C13,Mensual!$D$6:$H$163,5,0)) -> 0 | H13: =+G13*B13 -> 0
B14: 0.025 | C14: 6. Aumentar el ROA | D14: =IF(VLOOKUP($C14,Mensual!$D$6:$G$163,2,0)<0,0,VLOOKUP($C14,Mensual!$D$6:$G$163,2,0)) -> 0 | E14: =IF(VLOOKUP($C14,Mensual!$D$6:$G$163,3,0)<0,0,VLOOKUP($C14,Mensual!$D$6:$G$163,3,0)) -> 0.05 | F14: =IF(VLOOKUP($C14,Mensual!$D$6:$G$163,4,0)<0,0,VLOOKUP($C14,Mensual!$D$6:$G$163,4,0)) -> 1 | G14: =IF(VLOOKUP($C14,Mensual!$D$6:$H$163,5,0)<0,0,VLOOKUP($C14,Mensual!$D$6:$H$163,5,0)) -> 1 | H14: =+G14*B14 -> 0.025
B15: 0.1 | C15: 3.6 Cierres contables a mas tardar el 6 de cada mes | D15: =IF(VLOOKUP($C15,Mensual!$D$6:$G$163,2,0)<0,0,VLOOKUP($C15,Mensual!$D$6:$G$163,2,0)) -> # de cierres a tiempo | E15: =IF(VLOOKUP($C15,Mensual!$D$6:$G$163,3,0)<0,0,VLOOKUP($C15,Mensual!$D$6:$G$163,3,0)) -> 6 | F15: =IF(VLOOKUP($C15,Mensual!$D$6:$G$163,4,0)<0,0,VLOOKUP($C15,Mensual!$D$6:$G$163,4,0)) -> 6 | G15: =IF(VLOOKUP($C15,Mensual!$D$6:$H$163,5,0)<0,0,VLOOKUP($C15,Mensual!$D$6:$H$163,5,0)) -> 1 | H15: =+G15*B15 -> 0.1
B16: =SUM(B6:B15) -> 1 | H16: =SUM(H6:H15) -> 0.658125
C19: Colaboradores:
C20: Emilia Pineda
C21: Juan Manuel

Sheet Tesoreria
I1: 0.9
C2: Departamento: | D2: Administracion | I2: 80-90%
I3: Menos de 80%
A5: =+Mensual!B5 -> No | B5: =+Mensual!C5 -> Peso | D5: =+Mensual!E5 -> Unidad de medición | E5: =+Mensual!F5 -> Meta | F5: =+Mensual!G5 -> Resultado | G5: =+Mensual!H5 -> Nota | H5: =+Mensual!I5 -> Valor ponderado | I5: =+Mensual!J5 -> 0 | J5: =+Mensual!K5 -> 0.25 | K5: =+Mensual!L5 -> 0.5 | ... Q5: =+Mensual!R5 -> 0 | T5: Nota | U5: Nota
A6: =+Mensual!B6 -> 4 | B6: 0.3 | C6: 9. SCORE CARD Grupo EXA | D6: =IF(VLOOKUP($C6,Mensual!$D$6:$G$163,2,0)<0,0,VLOOKUP($C6,Mensual!$D$6:$G$163,2,0)) -> RESULTADO SCORECARD | E6: =IF(VLOOKUP($C6,Mensual!$D$6:$G$163,3,0)<0,0,VLOOKUP($C6,Mensual!$D$6:$G$163,3,0)) -> 1 | F6: =IF(VLOOKUP($C6,Mensual!$D$6:$G$163,4,0)<0,0,VLOOKUP($C6,Mensual!$D$6:$G$163,4,0)) -> 1.0325 | G6: =IF(VLOOKUP($C6,Mensual!$D$6:$H$163,5,0)<0,0,VLOOKUP($C6,Mensual!$D$6:$H$163,5,0)) -> 1.0325 | H6: =+G6*B6 -> 0.30975 | I6: =+Mensual!J6 -> 0 | J6: =+Mensual!K6 -> 0 | K6: =+Mensual!L6 -> 0 | L6: =+Mensual!M6 -> 0
B7: 0.1 | C7: 2.1 Reducir gasto administrativo x% | D7: =IF(VLOOKUP($C7,Mensual!$D$6:$G$163,2,0)<0,0,VLOOKUP($C7,Mensual!$D$6:$G$163,2,0)) -> % | E7: =IF(VLOOKUP($C7,Mensual!$D$6:$G$163,3,0)<0,0,VLOOKUP($C7,Mensual!$D$6:$G$163,3,0)) -> 0.1 | F7: =IF(VLOOKUP($C7,Mensual!$D$6:$G$163,4,0)<0,0,VLOOKUP($C7,Mensual!$D$6:$G$163,4,0)) -> 0.32 | G7: =IF(VLOOKUP($C7,Mensual!$D$6:$H$163,5,0)<0,0,VLOOKUP($C7,Mensual!$D$6:$H$163,5,0)) -> 1 | H7: =+G7*B7 -> 0.1
