Workbook

Sheet Summary
A1: KPI Evaluation Catalog — Working Classification
A3: Metric | B3: Value | D3: Evaluation Type | E3: Count | G3: Catalog Status | H3: Count
A4: Catalog records | B4: =COUNTA('KPI Catalog'!A2:A200) -> 89 | D4: GREATER_IS_BETTER | E4: =COUNTIF('KPI Catalog'!J2:J200,"GREATER_IS_BETTER") -> 48 | G4: PROPOSED | H4: =COUNTIF('KPI Catalog'!Q2:Q200,"PROPOSED") -> 56
A5: Atomic KPIs | B5: =COUNTIF('KPI Catalog'!D2:D200,"ATOMIC KPI") -> 73 | D5: LOWER_IS_BETTER | E5: =COUNTIF('KPI Catalog'!J2:J200,"LOWER_IS_BETTER") -> 21 | G5: BLOCKED | H5: =COUNTIF('KPI Catalog'!Q2:Q200,"BLOCKED") -> 28
A6: Feature / Milestone | B6: =COUNTIF('KPI Catalog'!D2:D200,"FEATURE / MILESTONE") -> 11 | D6: BINARY / MILESTONE | E6: =COUNTIF('KPI Catalog'!J2:J200,"BINARY / MILESTONE") -> 12 | G6: EXCLUDE / REVIEW | H6: =COUNTIF('KPI Catalog'!Q2:Q200,"EXCLUDE / REVIEW") -> 5
A7: Blocked / needs decision | B7: =COUNTIF('KPI Catalog'!Q2:Q200,"BLOCKED") -> 28 | D7: EQUAL_OR_LOWER_REVIEW | E7: =COUNTIF('KPI Catalog'!J2:J200,"EQUAL_OR_LOWER_REVIEW") -> 0
A8: Excluded / aggregates | B8: =COUNTIF('KPI Catalog'!Q2:Q200,"EXCLUDE / REVIEW") -> 5 | D8: NEEDS_REVIEW | E8: =COUNTIF('KPI Catalog'!J2:J200,"NEEDS_REVIEW") -> 8
A11: Category | B11: Count | D11: How to use this workbook
A12: Operational Productivity | B12: =COUNTIF('KPI Catalog'!E2:E200,"Operational Productivity") -> 15 | D12: 1. This is a proposed working classification, not an approved business rulebook.
A13: Commercial Growth | B13: =COUNTIF('KPI Catalog'!E2:E200,"Commercial Growth") -> 13 | D13: 2. Review BLOCKED items first; many have ambiguous result semantics, zero goals, or inconsistent legacy units/goals.
A14: Financial Performance | B14: =COUNTIF('KPI Catalog'!E2:E200,"Financial Performance") -> 13 | D14: 3. Evaluation Type answers whether higher/lower/equal/range is better; Scoring Method answers how Goal + Result becomes Compliance.
A15: Innovation & Digitalization | B15: =COUNTIF('KPI Catalog'!E2:E200,"Innovation & Digitalization") -> 12 | D15: 4. Result Semantics is critical: e.g. “reduce cost 10%” can mean lower actual cost OR higher achieved reduction percentage.
A16: Cost Efficiency | B16: =COUNTIF('KPI Catalog'!E2:E200,"Cost Efficiency") -> 11 | D16: 5. Source Occurrences preserves traceability back to the original workbook and shows where the same KPI was reused.
A17: Needs Business Review | B17: =COUNTIF('KPI Catalog'!E2:E200,"Needs Business Review") -> 10
A18: Asset Utilization | B18: =COUNTIF('KPI Catalog'!E2:E200,"Asset Utilization") -> 6
A19: Process & Service Quality | B19: =COUNTIF('KPI Catalog'!E2:E200,"Process & Service Quality") -> 4
A20: Safety & Risk | B20: =COUNTIF('KPI Catalog'!E2:E200,"Safety & Risk") -> 2
A21: Customer Experience | B21: =COUNTIF('KPI Catalog'!E2:E200,"Customer Experience") -> 1
A22: Financial Health | B22: =COUNTIF('KPI Catalog'!E2:E200,"Financial Health") -> 1
A23: People & Culture | B23: =COUNTIF('KPI Catalog'!E2:E200,"People & Culture") -> 1

Sheet KPI Catalog
A1: Catalog ID | B1: Legacy Code | C1: KPI Name / Original | D1: Row Type | E1: Category (Proposed) | F1: Primary Owner (Proposed) | G1: Result Semantics | H1: Measurement Unit (Proposed) | I1: Goal Example | J1: Evaluation Type (Proposed) | K1: Scoring Method (Proposed) | L1: Special Rule / Rationale | M1: Example Result (Source) | N1: Illustrative Raw Achievement % | O1: Illustrative Compliance % (cap 100) | P1: Classification Confidence | Q1: Catalog Status | R1: Business Review Required | S1: Review Reason | T1: KPI Family | U1: Source Department(s) | V1: Source Sheet(s) | W1: Occurrences | X1: Original Unit Variant(s) | Y1: Goal Variant(s) | Z1: Calculation Note | AA1: Action Priority | AB1: What Must Change / Confirm | AC1: Business Question / Decision | AD1: Recommended Next Status | AE1: Blocks Production Scoring for This KPI?
A2: CAT-001 | B2: 1 | C2: Aumentar ventas en el año 2023 del Grupo EXA (EXA, CONMOXA, AXA, TREXA, SAN JORGE) en 10% en USD vs año 2022. | D2: ATOMIC KPI | E2: Commercial Growth | F2: Contenedores / Ventas | G2: CHANGE_PERCENT | H2: % | I2: 0.1 | J2: GREATER_IS_BETTER | K2: PROPORTIONAL | L2: Mayor resultado = mejor; usar Result/Goal si el Goal es comparable. | M2: 0.2 | N2: 200 | O2: 100 | P2: MEDIUM | Q2: PROPOSED | R2: YES | S2: Confirmar que Result es porcentaje de cambio logrado y no valor absoluto. | T2: Sales & Commercial | V2: Hoja3 | W2: 2 | X2: Porcentaje | Y2: 0.1 | AA2: P1 - BUSINESS CONFIRMATION | AB2: Confirm Result Semantics and Goal interpretation; the current Greater/Lower proposal is plausible but not safe enough to approve automatically. | AC2: Confirmar que Result es porcentaje de cambio logrado y no valor absoluto. | AD2: APPROVED | AE2: YES for production
A3: CAT-002 | B3: 1 | C3: Aumentar ventas en: | D3: PARENT / AGGREGATE | E3: Commercial Growth | F3: Contenedores / Ventas | G3: CHANGE_PERCENT | H3: USD | I3: 0.2 | J3: GREATER_IS_BETTER | K3: PROPORTIONAL | L3: Mayor resultado = mejor; usar Result/Goal si el Goal es comparable. | P3: LOW | Q3: EXCLUDE / REVIEW | R3: YES | S3: No es un KPI atómico confiable para scoring. | T3: Sales & Commercial | V3: Hoja1 | W3: 1 | X3: Dólares | Y3: 0.2 | AA3: P3 - EXCLUDE/STRUCTURE | AB3: Do not score this row as an atomic KPI. Keep it only as a parent/group/Scorecard aggregate if the business still needs it. | AC3: Confirm that this row is an aggregate/header and should not generate an independent KPI result. | AD3: EXCLUDE / REVIEW | AE3: NO - exclude from atomic scoring
A4: CAT-003 | B4: 1.10 | C4: Aumentar ventas en articulos Sejue/get504 | D4: ATOMIC KPI | E4: Commercial Growth | F4: Contenedores / Ventas | G4: ABSOLUTE_VALUE | H4: artículos | I4: 10 | J4: GREATER_IS_BETTER | K4: PROPORTIONAL | L4: Mayor resultado = mejor; usar Result/Goal si el Goal es comparable. | M4: 19 | N4: 190 | O4: 100 | P4: HIGH | Q4: PROPOSED | R4: YES | S4: Clasificación propuesta con señales consistentes; requiere aprobación formal. | T4: Sales & Commercial | U4: Contenedores | V4: Contenedores, Luis Madrid | W4: 2 | X4: Articulos | Y4: 10 | AA4: P2 - APPROVAL | AB4: No formula change is currently suggested; obtain formal business approval and normalize any naming/unit variants. | AC4: Confirm KPI meaning, Goal, Unit, Evaluation Type and Scoring Method as proposed. | AD4: APPROVED | AE4: NO - formula can be tested
A5: CAT-004 | B5: 1.11 | C5: Tienda de conveniencia (Primeros 4 meses 15k usd y 25k usd) | D5: ATOMIC KPI | E5: Commercial Growth | F5: Gasolinera | G5: NEEDS_REVIEW | H5: USD | I5: 25000 | J5: NEEDS_REVIEW | K5: NEEDS_REVIEW | L5: No hay suficiente información inequívoca para decidir la fórmula. | M5: 20092.4 | P5: LOW | Q5: BLOCKED | R5: YES | S5: Semántica o dirección de evaluación ambigua. | T5: Other | U5: Gasolinera | V5: Abner U b, Gasolinera | W5: 2 | X5: Dólares | Y5: 25000 | AA5: P0 - BLOCKING | AB5: Must clarify what the Result actually represents; choose the Evaluation Type; define the Scoring Method before this KPI can be scored safely. | AC5: What does Result represent: absolute value, percentage change, compliance %, count, rate, duration, cost, ratio, or another value? Is higher better, lower better, exact target, range, or milestone/binary? How should Goal + Result be converted to Compliance %? | AD5: BLOCKED | AE5: YES
A6: CAT-005 | B6: 1.13 | C6: Aumentar servicio de almacenamiento y M&R San Lorenzo | D6: ATOMIC KPI | E6: Needs Business Review | F6: Predio San Lorenzo / Taller | G6: NEEDS_REVIEW | H6: REVIEW | I6: 0.2 | J6: GREATER_IS_BETTER | K6: PROPORTIONAL | L6: Mayor resultado = mejor; usar Result/Goal si el Goal es comparable. | M6: 0.3 | N6: 150 | O6: 100 | P6: LOW | Q6: BLOCKED | R6: YES | S6: Semántica o dirección de evaluación ambigua. | T6: Other | U6: Predio San Lorenzo | V6: Cubillo, San Lorenzo b | W6: 2 | X6: 0 | Y6: 0.2 | AA6: P0 - BLOCKING | AB6: Must clarify what the Result actually represents; normalize the Measurement Unit before this KPI can be scored safely. | AC6: What does Result represent: absolute value, percentage change, compliance %, count, rate, duration, cost, ratio, or another value? What exact unit should be stored and displayed for Result? | AD6: BLOCKED | AE6: YES
A7: CAT-006 | B7: 1.14 | C7: Incrementar gate out de contenedores Puerto Cortés | D7: ATOMIC KPI | E7: Commercial Growth | F7: Predio Puerto Cortés | G7: CHANGE_PERCENT | H7: gate-outs | I7: 0.2 | J7: GREATER_IS_BETTER | K7: PROPORTIONAL | L7: Mayor resultado = mejor; usar Result/Goal si el Goal es comparable. | M7: 0 | N7: 0 | O7: 0 | P7: MEDIUM | Q7: PROPOSED | R7: YES | S7: Confirmar que Result es porcentaje de cambio logrado y no valor absoluto. | T7: Sales & Commercial | U7: Predio Puerto Cortes | V7: Lorenzo Varela, Puerto Cortes | W7: 2 | X7: Gate | Y7: 0.2 | AA7: P1 - BUSINESS CONFIRMATION | AB7: Confirm Result Semantics and Goal interpretation; the current Greater/Lower proposal is plausible but not safe enough to approve automatically. | AC7: Confirmar que Result es porcentaje de cambio logrado y no valor absoluto. | AD7: APPROVED | AE7: YES for production
A8: CAT-007 | B8: 1.17 | C8: Aumentar el numero de cliente semestralmente | D8: ATOMIC KPI | E8: Commercial Growth | F8: Administracion | G8: CHANGE_PERCENT | H8: clientes | I8: 1 | J8: GREATER_IS_BETTER | K8: PROPORTIONAL | L8: Mayor resultado = mejor; usar Result/Goal si el Goal es comparable. | M8: 0 | N8: 0 | O8: 0 | P8: MEDIUM | Q8: PROPOSED | R8: YES | S8: Confirmar que Result es porcentaje de cambio logrado y no valor absoluto. | T8: Sales & Commercial | U8: Administracion | V8: TREXA | W8: 1 | X8: cliente | Y8: 1 | AA8: P1 - BUSINESS CONFIRMATION | AB8: Confirm Result Semantics and Goal interpretation; the current Greater/Lower proposal is plausible but not safe enough to approve automatically. | AC8: Confirmar que Result es porcentaje de cambio logrado y no valor absoluto. | AD8: APPROVED | AE8: YES for production
A9: CAT-008 | B9: 1.2 | C9: Lograr meta de contenedores | D9: ATOMIC KPI | E9: Needs Business Review | F9: Contenedores / Ventas | G9: NEEDS_REVIEW | H9: REVIEW | I9: 15 | J9: GREATER_IS_BETTER | K9: PROPORTIONAL | L9: Mayor resultado = mejor; usar Result/Goal si el Goal es comparable. | M9: 1 | N9: 6.6666667 | O9: 6.6666667 | P9: LOW | Q9: BLOCKED | R9: YES | S9: Semántica o dirección de evaluación ambigua. | T9: Other | U9: Contenedores | V9: Contenedores | W9: 1 | X9: 0 | Y9: 15 | AA9: P0 - BLOCKING | AB9: Must clarify what the Result actually represents; normalize the Measurement Unit before this KPI can be scored safely. | AC9: What does Result represent: absolute value, percentage change, compliance %, count, rate, duration, cost, ratio, or another value? What exact unit should be stored and displayed for Result? | AD9: BLOCKED | AE9: YES
A10: CAT-009 | B10: 1.3 | C10: Lograr meta de ventas contenedores secos y modificados(dolares) | D10: ATOMIC KPI | E10: Commercial Growth | F10: Contenedores / Ventas | G10: ABSOLUTE_VALUE | H10: USD | I10: 40000 | J10: GREATER_IS_BETTER | K10: PROPORTIONAL | L10: Mayor resultado = mejor; usar Result/Goal si el Goal es comparable. | M10: 1800 | N10: 4.5 | O10: 4.5 | P10: HIGH | Q10: PROPOSED | R10: YES | S10: Clasificación propuesta con señales consistentes; requiere aprobación formal. | T10: Sales & Commercial | U10: Contenedores | V10: Contenedores | W10: 1 | X10: Dólares | Y10: 40000 | AA10: P2 - APPROVAL | AB10: No formula change is currently suggested; obtain formal business approval and normalize any naming/unit variants. | AC10: Confirm KPI meaning, Goal, Unit, Evaluation Type and Scoring Method as proposed. | AD10: APPROVED | AE10: NO - formula can be tested
A11: CAT-010 | B11: 1.4 | C11: Lograr meta de ventas en alquileres de contenedores reefer (solo o en combo) | D11: ATOMIC KPI | E11: Commercial Growth | F11: Contenedores / Ventas | G11: ABSOLUTE_VALUE | H11: USD | I11: 16000 | J11: GREATER_IS_BETTER | K11: PROPORTIONAL | L11: Mayor resultado = mejor; usar Result/Goal si el Goal es comparable. | M11: 0 | N11: 0 | O11: 0 | P11: HIGH | Q11: PROPOSED | R11: YES | S11: Clasificación propuesta con señales consistentes; requiere aprobación formal. | T11: Sales & Commercial | U11: Contenedores | V11: Contenedores | W11: 1 | X11: Dólares | Y11: 16000 | AA11: P2 - APPROVAL | AB11: No formula change is currently suggested; obtain formal business approval and normalize any naming/unit variants. | AC11: Confirm KPI meaning, Goal, Unit, Evaluation Type and Scoring Method as proposed. | AD11: APPROVED | AE11: NO - formula can be tested
A12: CAT-011 | B12: 1.5 | C12: Aumentar Rentas bienes y raices | D12: ATOMIC KPI | E12: Commercial Growth | F12: Contenedores / Ventas | G12: CHANGE_PERCENT | H12: % | I12: 0.2 | J12: GREATER_IS_BETTER | K12: PROPORTIONAL | L12: Mayor resultado = mejor; usar Result/Goal si el Goal es comparable. | M12: 0 | N12: 0 | O12: 0 | P12: MEDIUM | Q12: PROPOSED | R12: YES | S12: Confirmar que Result es porcentaje de cambio logrado y no valor absoluto. | T12: Sales & Commercial | U12: Contenedores | V12: Luis Madrid | W12: 1 | X12: Porcentaje | Y12: 0.2 | AA12: P1 - BUSINESS CONFIRMATION | AB12: Confirm Result Semantics and Goal interpretation; the current Greater/Lower proposal is plausible but not safe enough to approve automatically. | AC12: Confirmar que Result es porcentaje de cambio logrado y no valor absoluto. | AD12: APPROVED | AE12: YES for production
A13: CAT-012 | B13: 1.6 | C13: Alquileres de contenedores secos (solo o en combos CONMOXA) | D13: ATOMIC KPI | E13: Commercial Growth | F13: Contenedores / Ventas | G13: CHANGE_PERCENT | H13: % | I13: 0.2 | J13: NEEDS_REVIEW | K13: NEEDS_REVIEW | L13: No hay suficiente información inequívoca para decidir la fórmula. | M13: 0.45 | P13: LOW | Q13: BLOCKED | R13: YES | S13: Semántica o dirección de evaluación ambigua. | T13: Sales & Commercial | U13: Contenedores | V13: Contenedores | W13: 1 | X13: Porcentaje | Y13: 0.2 | AA13: P0 - BLOCKING | AB13: Must choose the Evaluation Type; define the Scoring Method before this KPI can be scored safely. | AC13: Is higher better, lower better, exact target, range, or milestone/binary? How should Goal + Result be converted to Compliance %? | AD13: BLOCKED | AE13: YES
A14: CAT-013 | B14: 1.7 | C14: Lograr ventas de gasolinera de galones | D14: ATOMIC KPI | E14: Commercial Growth | F14: Gasolinera | G14: ABSOLUTE_VALUE | H14: galones | I14: 100000 | J14: GREATER_IS_BETTER | K14: PROPORTIONAL | L14: Mayor resultado = mejor; usar Result/Goal si el Goal es comparable. | M14: 112588 | N14: 112.588 | O14: 100 | P14: HIGH | Q14: PROPOSED | R14: YES | S14: Clasificación propuesta con señales consistentes; requiere aprobación formal. | T14: Sales & Commercial | U14: Gasolinera | V14: Abner U b, Gasolinera | W14: 2 | X14: Galones | Y14: 100000 | AA14: P2 - APPROVAL | AB14: No formula change is currently suggested; obtain formal business approval and normalize any naming/unit variants. | AC14: Confirm KPI meaning, Goal, Unit, Evaluation Type and Scoring Method as proposed. | AD14: APPROVED | AE14: NO - formula can be tested
A15: CAT-014 | B15: 1.8 | C15: Aumentar ventas en TREXA | D15: ATOMIC KPI | E15: Commercial Growth | F15: Contenedores / Ventas | G15: CHANGE_PERCENT | H15: USD | I15: 0.2 | J15: GREATER_IS_BETTER | K15: PROPORTIONAL | L15: Mayor resultado = mejor; usar Result/Goal si el Goal es comparable. | M15: 1.03 | N15: 515 | O15: 100 | P15: MEDIUM | Q15: PROPOSED | R15: YES | S15: Confirmar que Result es porcentaje de cambio logrado y no valor absoluto. | T15: Sales & Commercial | U15: Administracion | V15: Nancy Garcia b (4), TREXA | W15: 2 | X15: Dólares | Y15: 0.2 | AA15: P1 - BUSINESS CONFIRMATION | AB15: Confirm Result Semantics and Goal interpretation; the current Greater/Lower proposal is plausible but not safe enough to approve automatically. | AC15: Confirmar que Result es porcentaje de cambio logrado y no valor absoluto. | AD15: APPROVED | AE15: YES for production
A16: CAT-015 | B16: 1.9 | C16: Aumento en ventas de GPS a terceros (nuevos clientes) | D16: ATOMIC KPI | E16: Commercial Growth | F16: Contenedores / Ventas | G16: ABSOLUTE_VALUE | H16: unidades/mes | I16: 10 | J16: GREATER_IS_BETTER | K16: PROPORTIONAL | L16: Mayor resultado = mejor; usar Result/Goal si el Goal es comparable. | M16: 0 | N16: 0 | O16: 0 | P16: HIGH | Q16: PROPOSED | R16: YES | S16: Clasificación propuesta con señales consistentes; requiere aprobación formal. | T16: Sales & Commercial | U16: Contenedores, Sistemas Y Procesos | V16: Keila, Roy Reyes | W16: 2 | X16: Unidad instaladas / mensuales | Y16: 10 | AA16: P2 - APPROVAL | AB16: No formula change is currently suggested; obtain formal business approval and normalize any naming/unit variants. | AC16: Confirm KPI meaning, Goal, Unit, Evaluation Type and Scoring Method as proposed. | AD16: APPROVED | AE16: NO - formula can be tested
A17: CAT-016 | B17: 10 | C17: CONMOXA | D17: SCORECARD_AGGREGATE | E17: Needs Business Review | F17: Contenedores | G17: NEEDS_REVIEW | H17: RESULTADO SCORECARD | I17: 1 | J17: NEEDS_REVIEW | K17: NEEDS_REVIEW | L17: No hay suficiente información inequívoca para decidir la fórmula. | M17: 0.4255 | P17: LOW | Q17: EXCLUDE / REVIEW | R17: YES | S17: No es un KPI atómico confiable para scoring. | T17: Other | U17: Contenedores | V17: Luis Madrid, Roy Reyes | W17: 2 | X17: RESULTADO SCORECARD | Y17: 1 | AA17: P3 - EXCLUDE/STRUCTURE | AB17: Do not score this row as an atomic KPI. Keep it only as a parent/group/Scorecard aggregate if the business still needs it. | AC17: Confirm that this row is an aggregate/header and should not generate an independent KPI result. | AD17: EXCLUDE / REVIEW | AE17: NO - exclude from atomic scoring
A18: CAT-017 | B18: 2 | C18: Aumentar margen neto | D18: PARENT / AGGREGATE | E18: Financial Performance | F18: Administración / Finanzas | G18: RATIO_OR_PERCENT | H18: % | I18: 0.1 | J18: GREATER_IS_BETTER | K18: PROPORTIONAL | L18: Mayor resultado = mejor; usar Result/Goal si el Goal es comparable. | P18: LOW | Q18: EXCLUDE / REVIEW | R18: YES | S18: No es un KPI atómico confiable para scoring. | T18: Margins | V18: Hoja1 | W18: 1 | X18: Porcentaje | Y18: 0.1 | AA18: P3 - EXCLUDE/STRUCTURE | AB18: Do not score this row as an atomic KPI. Keep it only as a parent/group/Scorecard aggregate if the business still needs it. | AC18: Confirm that this row is an aggregate/header and should not generate an independent KPI result. | AD18: EXCLUDE / REVIEW | AE18: NO - exclude from atomic scoring
A19: CAT-018 | B19: 2 | C19: Aumentar margen neto vrs año anterior | D19: ATOMIC KPI | E19: Financial Performance | F19: Administración / Finanzas | G19: RATIO_OR_PERCENT | H19: % | I19: 0.1 | J19: GREATER_IS_BETTER | K19: PROPORTIONAL | L19: Mayor resultado = mejor; usar Result/Goal si el Goal es comparable. | M19: 0.1 | N19: 100 | O19: 100 | P19: HIGH | Q19: PROPOSED | R19: YES | S19: Clasificación propuesta con señales consistentes; requiere aprobación formal. | T19: Margins | V19: Hoja3 | W19: 2 | Y19: 0.1 | AA19: P2 - APPROVAL | AB19: No formula change is currently suggested; obtain formal business approval and normalize any naming/unit variants. | AC19: Confirm KPI meaning, Goal, Unit, Evaluation Type and Scoring Method as proposed. | AD19: APPROVED | AE19: NO - formula can be tested
A20: CAT-019 | B20: 2.1 | C20: Reducir gasto administrativo x% | D20: ATOMIC KPI | E20: Cost Efficiency | F20: Administración / Finanzas | G20: CHANGE_PERCENT | H20: % | I20: 0.1 | J20: GREATER_IS_BETTER | K20: PROPORTIONAL | L20: Result parece representar % de reducción lograda; confirmar semántica antes de aprobar. | M20: 0.32 | N20: 320 | O20: 100 | P20: MEDIUM | Q20: PROPOSED | R20: YES | S20: Confirmar que Result es porcentaje de cambio logrado y no valor absoluto. | T20: Costs & Efficiency | U20: Administracion | V20: Cecilia, Compras, Julio - Alejandro, Nancy Garcia b (4), Tesoreria | W20: 5 | X20: % | Y20: 0.1 | AA20: P1 - BUSINESS CONFIRMATION | AB20: Confirm Result Semantics and Goal interpretation; the current Greater/Lower proposal is plausible but not safe enough to approve automatically. | AC20: Confirmar que Result es porcentaje de cambio logrado y no valor absoluto. | AD20: APPROVED | AE20: YES for production
A21: CAT-020 | B21: 2.11 | C21: Gasto administrativo San Lorenzo | D21: ATOMIC KPI | E21: Cost Efficiency | F21: Administración / Finanzas | G21: UNIT_COST_OR_COST_RATE | H21: REVIEW | I21: 0.1 | J21: NEEDS_REVIEW | K21: NEEDS_REVIEW | L21: No hay suficiente información inequívoca para decidir la fórmula. | M21: 0 | P21: LOW | Q21: BLOCKED | R21: YES | S21: Semántica o dirección de evaluación ambigua. | T21: Costs & Efficiency | U21: Predio San Lorenzo | V21: Cubillo, San Lorenzo b | W21: 2 | X21: 0 | Y21: 0.1 | AA21: P0 - BLOCKING | AB21: Must normalize the Measurement Unit; choose the Evaluation Type; define the Scoring Method before this KPI can be scored safely. | AC21: What exact unit should be stored and displayed for Result? Is higher better, lower better, exact target, range, or milestone/binary? How should Goal + Result be converted to Compliance %? | AD21: BLOCKED | AE21: YES
A22: CAT-021 | B22: 2.12 | C22: Costo por mes por GPS (Costo de plataforma + Tigo/claro + otros costos) | D22: ATOMIC KPI | E22: Cost Efficiency | F22: Sistemas y Procesos | G22: UNIT_COST_OR_COST_RATE | H22: USD | I22: 8 | J22: NEEDS_REVIEW | K22: NEEDS_REVIEW | L22: No hay suficiente información inequívoca para decidir la fórmula. | M22: 4.71 | P22: LOW | Q22: BLOCKED | R22: YES | S22: Semántica o dirección de evaluación ambigua. | T22: Costs & Efficiency | U22: Sistemas Y Procesos | V22: Keila | W22: 1 | X22: $ | Y22: 8 | AA22: P0 - BLOCKING | AB22: Must choose the Evaluation Type; define the Scoring Method before this KPI can be scored safely. | AC22: Is higher better, lower better, exact target, range, or milestone/binary? How should Goal + Result be converted to Compliance %? | AD22: BLOCKED | AE22: YES
A23: CAT-022 | B23: 2.13 | C23: Reducir Costo de M&R por contenedor Puerto Cortes | D23: ATOMIC KPI | E23: Cost Efficiency | F23: Predio Puerto Cortés / Taller | G23: UNIT_COST_OR_COST_RATE | H23: USD/contenedor | I23: 0.1 | J23: LOWER_IS_BETTER | K23: PROPORTIONAL | L23: Menor valor real = mejor; usar Goal/Result si Goal>0. | M23: 0 | N23: 100 | O23: 100 | P23: HIGH | Q23: PROPOSED | R23: YES | S23: Clasificación propuesta con señales consistentes; requiere aprobación formal. | T23: Costs & Efficiency | U23: Predio Puerto Cortes | V23: Lorenzo Varela, Puerto Cortes | W23: 2 | X23: $/contenedor | Y23: 0.1 | Z23: Result=0 tratado como mejor que meta para ejemplo; revisar negocio. | AA23: P2 - APPROVAL | AB23: No formula change is currently suggested; obtain formal business approval and normalize any naming/unit variants. | AC23: Confirm KPI meaning, Goal, Unit, Evaluation Type and Scoring Method as proposed. | AD23: APPROVED | AE23: NO - formula can be tested
A24: CAT-023 | B24: 2.14 | C24: Reducir costo máquinas (incluye mulita y containers handler) Puerto Cortes | D24: ATOMIC KPI | E24: Cost Efficiency | F24: Predio Puerto Cortés / Taller | G24: UNIT_COST_OR_COST_RATE | H24: USD/contenedor | I24: 0.1 | J24: LOWER_IS_BETTER | K24: PROPORTIONAL | L24: Menor valor real = mejor; usar Goal/Result si Goal>0. | M24: 0 | N24: 100 | O24: 100 | P24: HIGH | Q24: PROPOSED | R24: YES | S24: Clasificación propuesta con señales consistentes; requiere aprobación formal. | T24: Costs & Efficiency | U24: Predio Puerto Cortes | V24: Lorenzo Varela, Puerto Cortes | W24: 2 | X24: $/contenedor | Y24: 0.1 | Z24: Result=0 tratado como mejor que meta para ejemplo; revisar negocio. | AA24: P2 - APPROVAL | AB24: No formula change is currently suggested; obtain formal business approval and normalize any naming/unit variants. | AC24: Confirm KPI meaning, Goal, Unit, Evaluation Type and Scoring Method as proposed. | AD24: APPROVED | AE24: NO - formula can be tested
A25: CAT-024 | B25: 2.15 | C25: Aumentar margen de M&R por contenedor San Lorenzo | D25: ATOMIC KPI | E25: Needs Business Review | F25: Predio San Lorenzo / Taller | G25: RATIO_OR_PERCENT | H25: % | I25: 0 | J25: GREATER_IS_BETTER | K25: PROPORTIONAL | L25: Mayor resultado = mejor; usar Result/Goal si el Goal es comparable. | M25: 0 | P25: LOW | Q25: BLOCKED | R25: YES | S25: Goal=0 no es compatible con scoring proporcional. | T25: Margins | U25: Predio San Lorenzo | V25: Cubillo, San Lorenzo b | W25: 2 | X25: 0 | Y25: 0 | AA25: P0 - BLOCKING | AB25: Resolve the documented ambiguity before using this KPI in production scoring. | AC25: Goal=0 no es compatible con scoring proporcional. | AD25: BLOCKED | AE25: YES
A26: CAT-025 | B26: 2.16 | C26: Reducir costo máquinas (incluye mulita y containers handler) San Lorenzo | D26: ATOMIC KPI | E26: Cost Efficiency | F26: Predio San Lorenzo / Taller | G26: UNIT_COST_OR_COST_RATE | H26: REVIEW | I26: 0 | J26: LOWER_IS_BETTER | K26: PROPORTIONAL | L26: Menor valor real = mejor; usar Goal/Result si Goal>0. | M26: 0 | P26: MEDIUM | Q26: PROPOSED | R26: YES | S26: Unidad de medida ausente/inconsistente; confirmar. | T26: Costs & Efficiency | U26: Predio San Lorenzo | V26: Cubillo, San Lorenzo b | W26: 2 | X26: 0 | Y26: 0 | AA26: P0 - BLOCKING | AB26: Must normalize the Measurement Unit before this KPI can be scored safely. | AC26: What exact unit should be stored and displayed for Result? | AD26: BLOCKED | AE26: YES
A27: CAT-026 | B27: 2.17 | C27: Reducir costo por km/cabezal TRANEXPA | D27: ATOMIC KPI | E27: Cost Efficiency | F27: Transporte | G27: UNIT_COST_OR_COST_RATE | H27: REVIEW | I27: 0 | J27: LOWER_IS_BETTER | K27: PROPORTIONAL | L27: Menor valor real = mejor; usar Goal/Result si Goal>0. | M27: 0.14 | P27: MEDIUM | Q27: PROPOSED | R27: YES | S27: Unidad de medida ausente/inconsistente; confirmar. | T27: Costs & Efficiency | U27: Transporte | V27: TRANEXPA | W27: 1 | X27: 0 | Y27: 0 | AA27: P0 - BLOCKING | AB27: Must normalize the Measurement Unit before this KPI can be scored safely. | AC27: What exact unit should be stored and displayed for Result? | AD27: BLOCKED | AE27: YES
A28: CAT-027 | B28: 2.18 | C28: Reducir M&R gensets $ /genset activo 10% | D28: ATOMIC KPI | E28: Needs Business Review | F28: Predio Puerto Cortes / Predio San Lorenzo | G28: NEEDS_REVIEW | H28: USD | I28: 0.1 | J28: LOWER_IS_BETTER | K28: PROPORTIONAL | L28: Menor valor real = mejor; usar Goal/Result si Goal>0. | M28: 4.66 | N28: 2.1459227 | O28: 2.1459227 | P28: LOW | Q28: BLOCKED | R28: YES | S28: Semántica o dirección de evaluación ambigua. | T28: Other | U28: Predio Puerto Cortes, Predio San Lorenzo | V28: Cubillo, Lorenzo Varela, Puerto Cortes, San Lorenzo b | W28: 4 | X28: dolares | Y28: 0.1 | AA28: P0 - BLOCKING | AB28: Must clarify what the Result actually represents before this KPI can be scored safely. | AC28: What does Result represent: absolute value, percentage change, compliance %, count, rate, duration, cost, ratio, or another value? | AD28: BLOCKED | AE28: YES
A29: CAT-028 | B29: 2.19 | C29: Gasto administrativo gasolinera 3%/ventas | D29: ATOMIC KPI | E29: Cost Efficiency | F29: Administración / Finanzas | G29: UNIT_COST_OR_COST_RATE | H29: USD | I29: 0.03 | J29: NEEDS_REVIEW | K29: NEEDS_REVIEW | L29: No hay suficiente información inequívoca para decidir la fórmula. | M29: 0.07 | P29: LOW | Q29: BLOCKED | R29: YES | S29: Semántica o dirección de evaluación ambigua. | T29: Costs & Efficiency | U29: Gasolinera | V29: Abner U b, Gasolinera | W29: 2 | X29: dolares | Y29: 0.03 | AA29: P0 - BLOCKING | AB29: Must choose the Evaluation Type; define the Scoring Method before this KPI can be scored safely. | AC29: Is higher better, lower better, exact target, range, or milestone/binary? How should Goal + Result be converted to Compliance %? | AD29: BLOCKED | AE29: YES
A30: CAT-029 | B30: 2.2 | C30: Reducir costo de M&R de chasis propios | D30: ATOMIC KPI | E30: Cost Efficiency | F30: Administracion / Predio Puerto Cortes / Predio San Lorenzo | G30: UNIT_COST_OR_COST_RATE | H30: USD/km | I30: 0.05 | J30: LOWER_IS_BETTER | K30: PROPORTIONAL | L30: Menor valor real = mejor; usar Goal/Result si Goal>0. | M30: 0.09 | N30: 55.555556 | O30: 55.555556 | P30: HIGH | Q30: PROPOSED | R30: YES | S30: Clasificación propuesta con señales consistentes; requiere aprobación formal. | T30: Costs & Efficiency | U30: Administracion, Predio Puerto Cortes, Predio San Lorenzo | V30: Compras, Cubillo, Lorenzo Varela, Puerto Cortes, San Lorenzo b | W30: 5 | X30: $/km | Y30: 0.05 | AA30: P2 - APPROVAL | AB30: No formula change is currently suggested; obtain formal business approval and normalize any naming/unit variants. | AC30: Confirm KPI meaning, Goal, Unit, Evaluation Type and Scoring Method as proposed. | AD30: APPROVED | AE30: NO - formula can be tested
A31: CAT-030 | B31: 2.20 | C31: Margen operativo de tienda | D31: ATOMIC KPI | E31: Financial Performance | F31: Administración / Finanzas | G31: RATIO_OR_PERCENT | H31: % | I31: 0.1 | J31: GREATER_IS_BETTER | K31: PROPORTIONAL | L31: Clasificación propuesta por semántica del resultado; requiere revisión del negocio. | M31: 0 | N31: 0 | O31: 0 | P31: HIGH | Q31: PROPOSED | R31: YES | S31: Clasificación propuesta con señales consistentes; requiere aprobación formal. | T31: Margins | U31: Gasolinera | V31: Abner U b, Gasolinera | W31: 2 | X31: 0 | Y31: 0.1 | AA31: P2 - APPROVAL | AB31: No formula change is currently suggested; obtain formal business approval and normalize any naming/unit variants. | AC31: Confirm KPI meaning, Goal, Unit, Evaluation Type and Scoring Method as proposed. | AD31: APPROVED | AE31: NO - formula can be tested
A32: CAT-031 | B32: 2.21 | C32: Aumentar % neto del servicio de transporte | D32: ATOMIC KPI | E32: Needs Business Review | F32: Servicio Al Cliente / Sistemas Y Procesos | G32: NEEDS_REVIEW | H32: % | I32: 0.1 | J32: GREATER_IS_BETTER | K32: PROPORTIONAL | L32: Mayor resultado = mejor; usar Result/Goal si el Goal es comparable. | M32: 0.1 | N32: 100 | O32: 100 | P32: LOW | Q32: BLOCKED | R32: YES | S32: Semántica o dirección de evaluación ambigua. | T32: Other | U32: Servicio Al Cliente, Sistemas Y Procesos | V32: Jacky, Servicio al cliente b, Yadira | W32: 3 | X32: 0 | Y32: 0.1 | AA32: P0 - BLOCKING | AB32: Must clarify what the Result actually represents before this KPI can be scored safely. | AC32: What does Result represent: absolute value, percentage change, compliance %, count, rate, duration, cost, ratio, or another value? | AD32: BLOCKED | AE32: YES
A33: CAT-032 | B33: 2.21 | C33: Margen operativo de la gasolinera | D33: ATOMIC KPI | E33: Financial Performance | F33: Administración / Finanzas | G33: RATIO_OR_PERCENT | H33: USD | I33: 0.1 | J33: GREATER_IS_BETTER | K33: PROPORTIONAL | L33: Clasificación propuesta por semántica del resultado; requiere revisión del negocio. | M33: 0.06 | N33: 60 | O33: 60 | P33: HIGH | Q33: PROPOSED | R33: YES | S33: Clasificación propuesta con señales consistentes; requiere aprobación formal. | T33: Margins | U33: Gasolinera | V33: Abner U b, Gasolinera | W33: 2 | X33: dolares | Y33: 0.1 | AA33: P2 - APPROVAL | AB33: No formula change is currently suggested; obtain formal business approval and normalize any naming/unit variants. | AC33: Confirm KPI meaning, Goal, Unit, Evaluation Type and Scoring Method as proposed. | AD33: APPROVED | AE33: NO - formula can be tested
A34: CAT-033 | B34: 2.22 | C34: Aumentar margen neto alquiler de contenedores secos (solo o en combo) TREXA | D34: ATOMIC KPI | E34: Financial Performance | F34: Administración / Finanzas | G34: RATIO_OR_PERCENT | H34: % | I34: 0.1 | J34: GREATER_IS_BETTER | K34: PROPORTIONAL | L34: Mayor resultado = mejor; usar Result/Goal si el Goal es comparable. | M34: 0.1 | N34: 100 | O34: 100 | P34: HIGH | Q34: PROPOSED | R34: YES | S34: Clasificación propuesta con señales consistentes; requiere aprobación formal. | T34: Margins | U34: Administracion | V34: TREXA | W34: 1 | X34: 0 | Y34: 0.1 | AA34: P2 - APPROVAL | AB34: No formula change is currently suggested; obtain formal business approval and normalize any naming/unit variants. | AC34: Confirm KPI meaning, Goal, Unit, Evaluation Type and Scoring Method as proposed. | AD34: APPROVED | AE34: NO - formula can be tested
A35: CAT-034 | B35: 2.3 | C35: Reducir Costo por km cabezales propios. | D35: ATOMIC KPI | E35: Cost Efficiency | F35: Transporte | G35: UNIT_COST_OR_COST_RATE | H35: USD | I35: 0.05 | J35: LOWER_IS_BETTER | K35: PROPORTIONAL | L35: Menor valor real = mejor; usar Goal/Result si Goal>0. | M35: 0.6 | N35: 8.3333333 | O35: 8.3333333 | P35: HIGH | Q35: PROPOSED | R35: YES | S35: Clasificación propuesta con señales consistentes; requiere aprobación formal. | T35: Costs & Efficiency | U35: Administracion, Transporte | V35: Cecilia, Compras, Nancy Garcia b (4), TRANEXPA | W35: 5 | X35: $ | Y35: 0.05 | AA35: P2 - APPROVAL | AB35: No formula change is currently suggested; obtain formal business approval and normalize any naming/unit variants. | AC35: Confirm KPI meaning, Goal, Unit, Evaluation Type and Scoring Method as proposed. | AD35: APPROVED | AE35: NO - formula can be tested
A36: CAT-035 | B36: 2.5 | C36: Aumentar Margen neto en venta de contenedores (modificados y secos) | D36: ATOMIC KPI | E36: Financial Performance | F36: Administración / Finanzas | G36: RATIO_OR_PERCENT | H36: % | I36: 0.1 | J36: GREATER_IS_BETTER | K36: PROPORTIONAL | L36: Mayor resultado = mejor; usar Result/Goal si el Goal es comparable. | M36: 0 | N36: 0 | O36: 0 | P36: HIGH | Q36: PROPOSED | R36: YES | S36: Clasificación propuesta con señales consistentes; requiere aprobación formal. | T36: Margins | U36: Contenedores | V36: Contenedores | W36: 1 | X36: % | Y36: 0.1 | AA36: P2 - APPROVAL | AB36: No formula change is currently suggested; obtain formal business approval and normalize any naming/unit variants. | AC36: Confirm KPI meaning, Goal, Unit, Evaluation Type and Scoring Method as proposed. | AD36: APPROVED | AE36: NO - formula can be tested
A37: CAT-036 | B37: 2.6 | C37: Aumento en 20% en margen de contribución bruta venta de contenedores | D37: ATOMIC KPI | E37: Financial Performance | F37: Administración / Finanzas | G37: RATIO_OR_PERCENT | H37: USD | I37: 0.2 | J37: GREATER_IS_BETTER | K37: PROPORTIONAL | L37: Mayor resultado = mejor; usar Result/Goal si el Goal es comparable. | M37: 0 | N37: 0 | O37: 0 | P37: HIGH | Q37: PROPOSED | R37: YES | S37: Clasificación propuesta con señales consistentes; requiere aprobación formal. | T37: Margins | U37: Contenedores | V37: Contenedores | W37: 1 | X37: $ | Y37: 0.2 | AA37: P2 - APPROVAL | AB37: No formula change is currently suggested; obtain formal business approval and normalize any naming/unit variants. | AC37: Confirm KPI meaning, Goal, Unit, Evaluation Type and Scoring Method as proposed. | AD37: APPROVED | AE37: NO - formula can be tested
A38: CAT-037 | B38: 2.7 | C38: Aumento en 20% en margen de contribución bruta alquiler de bodegas | D38: ATOMIC KPI | E38: Financial Performance | F38: Administración / Finanzas | G38: RATIO_OR_PERCENT | H38: USD | I38: 0.2 | J38: GREATER_IS_BETTER | K38: PROPORTIONAL | L38: Mayor resultado = mejor; usar Result/Goal si el Goal es comparable. | M38: 0 | N38: 0 | O38: 0 | P38: HIGH | Q38: PROPOSED | R38: YES | S38: Clasificación propuesta con señales consistentes; requiere aprobación formal. | T38: Margins | U38: Contenedores | V38: Contenedores | W38: 1 | X38: $ | Y38: 0.2 | AA38: P2 - APPROVAL | AB38: No formula change is currently suggested; obtain formal business approval and normalize any naming/unit variants. | AC38: Confirm KPI meaning, Goal, Unit, Evaluation Type and Scoring Method as proposed. | AD38: APPROVED | AE38: NO - formula can be tested
A39: CAT-038 | B39: 2.8 | C39: Aumento en 20% en margen de contribución bruta alquiler de reefers. | D39: ATOMIC KPI | E39: Financial Performance | F39: Administración / Finanzas | G39: RATIO_OR_PERCENT | H39: USD | I39: 0.2 | J39: GREATER_IS_BETTER | K39: PROPORTIONAL | L39: Mayor resultado = mejor; usar Result/Goal si el Goal es comparable. | M39: 0 | N39: 0 | O39: 0 | P39: HIGH | Q39: PROPOSED | R39: YES | S39: Clasificación propuesta con señales consistentes; requiere aprobación formal. | T39: Margins | U39: Contenedores | V39: Contenedores | W39: 1 | X39: $ | Y39: 0.2 | AA39: P2 - APPROVAL | AB39: No formula change is currently suggested; obtain formal business approval and normalize any naming/unit variants. | AC39: Confirm KPI meaning, Goal, Unit, Evaluation Type and Scoring Method as proposed. | AD39: APPROVED | AE39: NO - formula can be tested
A40: CAT-039 | B40: 2.9 | C40: Reducir Costo administrativo Puerto Cortés con relacion al año anterior | D40: ATOMIC KPI | E40: Cost Efficiency | F40: Predio Puerto Cortés | G40: UNIT_COST_OR_COST_RATE | H40: REVIEW | I40: 0.05 | J40: LOWER_IS_BETTER | K40: PROPORTIONAL | L40: Menor valor real = mejor; usar Goal/Result si Goal>0. | M40: 0 | N40: 100 | O40: 100 | P40: MEDIUM | Q40: PROPOSED | R40: YES | S40: Unidad de medida ausente/inconsistente; confirmar. | T40: Costs & Efficiency | U40: Predio Puerto Cortes | V40: Lorenzo Varela, Puerto Cortes | W40: 2 | X40: 0 | Y40: 0.05 | Z40: Result=0 tratado como mejor que meta para ejemplo; revisar negocio. | AA40: P0 - BLOCKING | AB40: Must normalize the Measurement Unit before this KPI can be scored safely. | AC40: What exact unit should be stored and displayed for Result? | AD40: BLOCKED | AE40: YES
...

Sheet Review Queue
A1: Catalog ID | B1: Legacy Code | C1: KPI Name / Original | D1: Row Type | E1: Category (Proposed) | F1: Primary Owner (Proposed) | G1: Result Semantics | H1: Measurement Unit (Proposed) | I1: Goal Example | J1: Evaluation Type (Proposed) | K1: Scoring Method (Proposed) | L1: Catalog Status | M1: Classification Confidence | N1: Review Reason | O1: Source Sheet(s) | P1: Action Priority | Q1: What Must Change / Confirm | R1: Business Question / Decision
A2: CAT-001 | B2: 1 | C2: Aumentar ventas en el año 2023 del Grupo EXA (EXA, CONMOXA, AXA, TREXA, SAN JORGE) en 10% en USD vs año 2022. | D2: ATOMIC KPI | E2: Commercial Growth | F2: Contenedores / Ventas | G2: CHANGE_PERCENT | H2: % | I2: 0.1 | J2: GREATER_IS_BETTER | K2: PROPORTIONAL | L2: PROPOSED | M2: MEDIUM | N2: Confirmar que Result es porcentaje de cambio logrado y no valor absoluto. | O2: Hoja3 | P2: P1 - BUSINESS CONFIRMATION | Q2: Confirm Result Semantics and Goal interpretation; the current Greater/Lower proposal is plausible but not safe enough to approve automatically. | R2: Confirmar que Result es porcentaje de cambio logrado y no valor absoluto.
A3: CAT-002 | B3: 1 | C3: Aumentar ventas en: | D3: PARENT / AGGREGATE | E3: Commercial Growth | F3: Contenedores / Ventas | G3: CHANGE_PERCENT | H3: USD | I3: 0.2 | J3: GREATER_IS_BETTER | K3: PROPORTIONAL | L3: EXCLUDE / REVIEW | M3: LOW | N3: No es un KPI atómico confiable para scoring. | O3: Hoja1 | P3: P3 - EXCLUDE/STRUCTURE | Q3: Do not score this row as an atomic KPI. Keep it only as a parent/group/Scorecard aggregate if the business still needs it. | R3: Confirm that this row is an aggregate/header and should not generate an independent KPI result.
A4: CAT-004 | B4: 1.11 | C4: Tienda de conveniencia (Primeros 4 meses 15k usd y 25k usd) | D4: ATOMIC KPI | E4: Commercial Growth | F4: Gasolinera | G4: NEEDS_REVIEW | H4: USD | I4: 25000 | J4: NEEDS_REVIEW | K4: NEEDS_REVIEW | L4: BLOCKED | M4: LOW | N4: Semántica o dirección de evaluación ambigua. | O4: Abner U b, Gasolinera | P4: P0 - BLOCKING | Q4: Must clarify what the Result actually represents; choose the Evaluation Type; define the Scoring Method before this KPI can be scored safely. | R4: What does Result represent: absolute value, percentage change, compliance %, count, rate, duration, cost, ratio, or another value? Is higher better, lower better, exact target, range, or milestone/binary? How should Goal + Result be converted to Compliance %?
A5: CAT-005 | B5: 1.13 | C5: Aumentar servicio de almacenamiento y M&R San Lorenzo | D5: ATOMIC KPI | E5: Needs Business Review | F5: Predio San Lorenzo / Taller | G5: NEEDS_REVIEW | H5: REVIEW | I5: 0.2 | J5: GREATER_IS_BETTER | K5: PROPORTIONAL | L5: BLOCKED | M5: LOW | N5: Semántica o dirección de evaluación ambigua. | O5: Cubillo, San Lorenzo b | P5: P0 - BLOCKING | Q5: Must clarify what the Result actually represents; normalize the Measurement Unit before this KPI can be scored safely. | R5: What does Result represent: absolute value, percentage change, compliance %, count, rate, duration, cost, ratio, or another value? What exact unit should be stored and displayed for Result?
A6: CAT-006 | B6: 1.14 | C6: Incrementar gate out de contenedores Puerto Cortés | D6: ATOMIC KPI | E6: Commercial Growth | F6: Predio Puerto Cortés | G6: CHANGE_PERCENT | H6: gate-outs | I6: 0.2 | J6: GREATER_IS_BETTER | K6: PROPORTIONAL | L6: PROPOSED | M6: MEDIUM | N6: Confirmar que Result es porcentaje de cambio logrado y no valor absoluto. | O6: Lorenzo Varela, Puerto Cortes | P6: P1 - BUSINESS CONFIRMATION | Q6: Confirm Result Semantics and Goal interpretation; the current Greater/Lower proposal is plausible but not safe enough to approve automatically. | R6: Confirmar que Result es porcentaje de cambio logrado y no valor absoluto.
A7: CAT-007 | B7: 1.17 | C7: Aumentar el numero de cliente semestralmente | D7: ATOMIC KPI | E7: Commercial Growth | F7: Administracion | G7: CHANGE_PERCENT | H7: clientes | I7: 1 | J7: GREATER_IS_BETTER | K7: PROPORTIONAL | L7: PROPOSED | M7: MEDIUM | N7: Confirmar que Result es porcentaje de cambio logrado y no valor absoluto. | O7: TREXA | P7: P1 - BUSINESS CONFIRMATION | Q7: Confirm Result Semantics and Goal interpretation; the current Greater/Lower proposal is plausible but not safe enough to approve automatically. | R7: Confirmar que Result es porcentaje de cambio logrado y no valor absoluto.
A8: CAT-008 | B8: 1.2 | C8: Lograr meta de contenedores | D8: ATOMIC KPI | E8: Needs Business Review | F8: Contenedores / Ventas | G8: NEEDS_REVIEW | H8: REVIEW | I8: 15 | J8: GREATER_IS_BETTER | K8: PROPORTIONAL | L8: BLOCKED | M8: LOW | N8: Semántica o dirección de evaluación ambigua. | O8: Contenedores | P8: P0 - BLOCKING | Q8: Must clarify what the Result actually represents; normalize the Measurement Unit before this KPI can be scored safely. | R8: What does Result represent: absolute value, percentage change, compliance %, count, rate, duration, cost, ratio, or another value? What exact unit should be stored and displayed for Result?
A9: CAT-011 | B9: 1.5 | C9: Aumentar Rentas bienes y raices | D9: ATOMIC KPI | E9: Commercial Growth | F9: Contenedores / Ventas | G9: CHANGE_PERCENT | H9: % | I9: 0.2 | J9: GREATER_IS_BETTER | K9: PROPORTIONAL | L9: PROPOSED | M9: MEDIUM | N9: Confirmar que Result es porcentaje de cambio logrado y no valor absoluto. | O9: Luis Madrid | P9: P1 - BUSINESS CONFIRMATION | Q9: Confirm Result Semantics and Goal interpretation; the current Greater/Lower proposal is plausible but not safe enough to approve automatically. | R9: Confirmar que Result es porcentaje de cambio logrado y no valor absoluto.
A10: CAT-012 | B10: 1.6 | C10: Alquileres de contenedores secos (solo o en combos CONMOXA) | D10: ATOMIC KPI | E10: Commercial Growth | F10: Contenedores / Ventas | G10: CHANGE_PERCENT | H10: % | I10: 0.2 | J10: NEEDS_REVIEW | K10: NEEDS_REVIEW | L10: BLOCKED | M10: LOW | N10: Semántica o dirección de evaluación ambigua. | O10: Contenedores | P10: P0 - BLOCKING | Q10: Must choose the Evaluation Type; define the Scoring Method before this KPI can be scored safely. | R10: Is higher better, lower better, exact target, range, or milestone/binary? How should Goal + Result be converted to Compliance %?
A11: CAT-014 | B11: 1.8 | C11: Aumentar ventas en TREXA | D11: ATOMIC KPI | E11: Commercial Growth | F11: Contenedores / Ventas | G11: CHANGE_PERCENT | H11: USD | I11: 0.2 | J11: GREATER_IS_BETTER | K11: PROPORTIONAL | L11: PROPOSED | M11: MEDIUM | N11: Confirmar que Result es porcentaje de cambio logrado y no valor absoluto. | O11: Nancy Garcia b (4), TREXA | P11: P1 - BUSINESS CONFIRMATION | Q11: Confirm Result Semantics and Goal interpretation; the current Greater/Lower proposal is plausible but not safe enough to approve automatically. | R11: Confirmar que Result es porcentaje de cambio logrado y no valor absoluto.
A12: CAT-016 | B12: 10 | C12: CONMOXA | D12: SCORECARD_AGGREGATE | E12: Needs Business Review | F12: Contenedores | G12: NEEDS_REVIEW | H12: RESULTADO SCORECARD | I12: 1 | J12: NEEDS_REVIEW | K12: NEEDS_REVIEW | L12: EXCLUDE / REVIEW | M12: LOW | N12: No es un KPI atómico confiable para scoring. | O12: Luis Madrid, Roy Reyes | P12: P3 - EXCLUDE/STRUCTURE | Q12: Do not score this row as an atomic KPI. Keep it only as a parent/group/Scorecard aggregate if the business still needs it. | R12: Confirm that this row is an aggregate/header and should not generate an independent KPI result.
A13: CAT-017 | B13: 2 | C13: Aumentar margen neto | D13: PARENT / AGGREGATE | E13: Financial Performance | F13: Administración / Finanzas | G13: RATIO_OR_PERCENT | H13: % | I13: 0.1 | J13: GREATER_IS_BETTER | K13: PROPORTIONAL | L13: EXCLUDE / REVIEW | M13: LOW | N13: No es un KPI atómico confiable para scoring. | O13: Hoja1 | P13: P3 - EXCLUDE/STRUCTURE | Q13: Do not score this row as an atomic KPI. Keep it only as a parent/group/Scorecard aggregate if the business still needs it. | R13: Confirm that this row is an aggregate/header and should not generate an independent KPI result.
... A41: CAT-078 | B41: 8 | C41: Innovaciones estratégicas de sistemas de Impacto recurrente | D41: PARENT / AGGREGATE | E41: Innovation & Digitalization | F41: Sistemas y Procesos | G41: BINARY_OR_MILESTONE | H41: estado / hito | I41: 1 | J41: BINARY / MILESTONE | K41: BINARY_OR_MILESTONE | L41: EXCLUDE / REVIEW | M41: LOW | N41: No es un KPI atómico confiable para scoring. | O41: David Molina, Desarrollo, Hoja1, Hoja3 | P41: P3 - EXCLUDE/STRUCTURE | Q41: Do not score this row as an atomic KPI. Keep it only as a parent/group/Scorecard aggregate if the business still needs it. | R41: Confirm that this row is an aggregate/header and should not generate an independent KPI result.
A42: CAT-079 | B42: 8.1 | C42: Integracion EMS - Hapag-Lloyd | D42: FEATURE / MILESTONE | E42: Innovation & Digitalization | F42: Sistemas y Procesos | G42: BINARY_OR_MILESTONE | H42: estado / hito | J42: BINARY / MILESTONE | K42: BINARY_OR_MILESTONE | L42: BLOCKED | M42: LOW | N42: Falta definir formalmente estados/hitos y scoring Binary/Milestone. | O42: Hoja1 | P42: P1 - RULE DEFINITION | Q42: Decide whether this is BINARY or MILESTONE-based, then define the allowed states/milestones and their Compliance mapping. | R42: Is success only Completed/Not Completed, or are intermediate milestones valid? What Compliance % maps to each state?
A43: CAT-080 | B43: 8.10 | C43: Depot - EMS | D43: FEATURE / MILESTONE | E43: Innovation & Digitalization | F43: Sistemas y Procesos | G43: BINARY_OR_MILESTONE | H43: REVIEW | J43: BINARY / MILESTONE | K43: BINARY_OR_MILESTONE | L43: BLOCKED | M43: LOW | N43: Falta definir formalmente estados/hitos y scoring Binary/Milestone. | O43: Hoja1 | P43: P1 - RULE DEFINITION | Q43: Decide whether this is BINARY or MILESTONE-based, then define the allowed states/milestones and their Compliance mapping. | R43: Is success only Completed/Not Completed, or are intermediate milestones valid? What Compliance % maps to each state?
A44: CAT-081 | B44: 8.11 | C44: Multireport | D44: FEATURE / MILESTONE | E44: Innovation & Digitalization | F44: Sistemas y Procesos | G44: BINARY_OR_MILESTONE | H44: estado / hito | J44: BINARY / MILESTONE | K44: BINARY_OR_MILESTONE | L44: BLOCKED | M44: LOW | N44: Falta definir formalmente estados/hitos y scoring Binary/Milestone. | O44: Hoja1 | P44: P1 - RULE DEFINITION | Q44: Decide whether this is BINARY or MILESTONE-based, then define the allowed states/milestones and their Compliance mapping. | R44: Is success only Completed/Not Completed, or are intermediate milestones valid? What Compliance % maps to each state?
A45: CAT-082 | B45: 8.2 | C45: Integracion EMS - GPS | D45: FEATURE / MILESTONE | E45: Innovation & Digitalization | F45: Sistemas y Procesos | G45: BINARY_OR_MILESTONE | H45: estado / hito | J45: BINARY / MILESTONE | K45: BINARY_OR_MILESTONE | L45: BLOCKED | M45: LOW | N45: Falta definir formalmente estados/hitos y scoring Binary/Milestone. | O45: Hoja1 | P45: P1 - RULE DEFINITION | Q45: Decide whether this is BINARY or MILESTONE-based, then define the allowed states/milestones and their Compliance mapping. | R45: Is success only Completed/Not Completed, or are intermediate milestones valid? What Compliance % maps to each state?
A46: CAT-083 | B46: 8.3 | C46: Integracion EMS - SAP | D46: FEATURE / MILESTONE | E46: Innovation & Digitalization | F46: Sistemas y Procesos | G46: BINARY_OR_MILESTONE | H46: estado / hito | J46: BINARY / MILESTONE | K46: BINARY_OR_MILESTONE | L46: BLOCKED | M46: LOW | N46: Falta definir formalmente estados/hitos y scoring Binary/Milestone. | O46: Hoja1 | P46: P1 - RULE DEFINITION | Q46: Decide whether this is BINARY or MILESTONE-based, then define the allowed states/milestones and their Compliance mapping. | R46: Is success only Completed/Not Completed, or are intermediate milestones valid? What Compliance % maps to each state?
A47: CAT-084 | B47: 8.4 | C47: Integracion EMS - Gasolinera | D47: FEATURE / MILESTONE | E47: Innovation & Digitalization | F47: Sistemas y Procesos | G47: BINARY_OR_MILESTONE | H47: estado / hito | J47: BINARY / MILESTONE | K47: BINARY_OR_MILESTONE | L47: BLOCKED | M47: LOW | N47: Falta definir formalmente estados/hitos y scoring Binary/Milestone. | O47: Hoja1 | P47: P1 - RULE DEFINITION | Q47: Decide whether this is BINARY or MILESTONE-based, then define the allowed states/milestones and their Compliance mapping. | R47: Is success only Completed/Not Completed, or are intermediate milestones valid? What Compliance % maps to each state?
A48: CAT-085 | B48: 8.5 | C48: Planilla de motorista | D48: FEATURE / MILESTONE | E48: Innovation & Digitalization | F48: Needs Business Review | G48: BINARY_OR_MILESTONE | H48: REVIEW | J48: BINARY / MILESTONE | K48: BINARY_OR_MILESTONE | L48: BLOCKED | M48: LOW | N48: Falta definir formalmente estados/hitos y scoring Binary/Milestone. | O48: Hoja1 | P48: P1 - RULE DEFINITION | Q48: Decide whether this is BINARY or MILESTONE-based, then define the allowed states/milestones and their Compliance mapping. | R48: Is success only Completed/Not Completed, or are intermediate milestones valid? What Compliance % maps to each state?
A49: CAT-086 | B49: 8.6 | C49: Reset Module | D49: FEATURE / MILESTONE | E49: Innovation & Digitalization | F49: Sistemas y Procesos | G49: BINARY_OR_MILESTONE | H49: estado / hito | J49: BINARY / MILESTONE | K49: BINARY_OR_MILESTONE | L49: BLOCKED | M49: LOW | N49: Falta definir formalmente estados/hitos y scoring Binary/Milestone. | O49: Hoja1 | P49: P1 - RULE DEFINITION | Q49: Decide whether this is BINARY or MILESTONE-based, then define the allowed states/milestones and their Compliance mapping. | R49: Is success only Completed/Not Completed, or are intermediate milestones valid? What Compliance % maps to each state?
A50: CAT-087 | B50: 8.7 | C50: Add on SAP | D50: FEATURE / MILESTONE | E50: Innovation & Digitalization | F50: Sistemas y Procesos | G50: BINARY_OR_MILESTONE | H50: estado / hito | J50: BINARY / MILESTONE | K50: BINARY_OR_MILESTONE | L50: BLOCKED | M50: LOW | N50: Falta definir formalmente estados/hitos y scoring Binary/Milestone. | O50: Hoja1 | P50: P1 - RULE DEFINITION | Q50: Decide whether this is BINARY or MILESTONE-based, then define the allowed states/milestones and their Compliance mapping. | R50: Is success only Completed/Not Completed, or are intermediate milestones valid? What Compliance % maps to each state?
A51: CAT-088 | B51: 8.8 | C51: Multilanguage | D51: FEATURE / MILESTONE | E51: Innovation & Digitalization | F51: Sistemas y Procesos | G51: BINARY_OR_MILESTONE | H51: estado / hito | J51: BINARY / MILESTONE | K51: BINARY_OR_MILESTONE | L51: BLOCKED | M51: LOW | N51: Falta definir formalmente estados/hitos y scoring Binary/Milestone. | O51: Hoja1 | P51: P1 - RULE DEFINITION | Q51: Decide whether this is BINARY or MILESTONE-based, then define the allowed states/milestones and their Compliance mapping. | R51: Is success only Completed/Not Completed, or are intermediate milestones valid? What Compliance % maps to each state?
A52: CAT-089 | B52: 8.9 | C52: Multicompany | D52: FEATURE / MILESTONE | E52: Innovation & Digitalization | F52: Sistemas y Procesos | G52: BINARY_OR_MILESTONE | H52: estado / hito | J52: BINARY / MILESTONE | K52: BINARY_OR_MILESTONE | L52: BLOCKED | M52: LOW | N52: Falta definir formalmente estados/hitos y scoring Binary/Milestone. | O52: Hoja1 | P52: P1 - RULE DEFINITION | Q52: Decide whether this is BINARY or MILESTONE-based, then define the allowed states/milestones and their Compliance mapping. | R52: Is success only Completed/Not Completed, or are intermediate milestones valid? What Compliance % maps to each state?

Sheet Source Occurrences
A1: Catalog ID | B1: Source Sheet | C1: Source Row | D1: Source Department | E1: Source Collaborator | F1: Original KPI Description | G1: Original Unit | H1: Original Goal | I1: Original Result | J1: Original Weight
A2: CAT-008 | B2: Contenedores | C2: 6 | D2: Contenedores | F2: 1.2 Lograr meta de contenedores | G2: 0 | H2: 15 | I2: 1 | J2: 0.3
A3: CAT-012 | B3: Contenedores | C3: 8 | D3: Contenedores | F3: 1.6 Alquileres de contenedores secos (solo o en combos CONMOXA) | G3: Porcentaje | H3: 0.2 | I3: 0.45 | J3: 0.05
A4: CAT-010 | B4: Contenedores | C4: 9 | D4: Contenedores | F4: 1.4 Lograr meta de ventas en alquileres de contenedores reefer (solo o en combo) | G4: Dólares | H4: 16000 | I4: 0 | J4: 0.05
A5: CAT-009 | B5: Contenedores | C5: 10 | D5: Contenedores | F5: 1.3 Lograr meta de ventas contenedores secos y modificados(dolares) | G5: Dólares | H5: 40000 | I5: 1800 | J5: 0.05
A6: CAT-035 | B6: Contenedores | C6: 11 | D6: Contenedores | F6: 2.5 Aumentar Margen neto en venta de contenedores (modificados y secos) | G6: % | H6: 0.1 | I6: 0 | J6: 0.05
A7: CAT-036 | B7: Contenedores | C7: 12 | D7: Contenedores | F7: 2.6 Aumento en 20% en margen de contribución bruta venta de contenedores | G7: $ | H7: 0.2 | I7: 0 | J7: 0.05
A8: CAT-003 | B8: Contenedores | C8: 13 | D8: Contenedores | F8: 1.10 Aumentar ventas en articulos Sejue/get504 | G8: Articulos | H8: 10 | I8: 19 | J8: 0.25
A9: CAT-003 | B9: Luis Madrid | C9: 8 | D9: Contenedores | E9: Luis Madrid | F9: 1.10 Aumentar ventas en articulos Sejue/get504 | G9: Articulos | H9: 10 | I9: 19 | J9: 0.1
A10: CAT-038 | B10: Contenedores | C10: 14 | D10: Contenedores | F10: 2.8 Aumento en 20% en margen de contribución bruta alquiler de reefers. | G10: $ | H10: 0.2 | I10: 0 | J10: 0.05
A11: CAT-037 | B11: Contenedores | C11: 15 | D11: Contenedores | F11: 2.7 Aumento en 20% en margen de contribución bruta alquiler de bodegas | G11: $ | H11: 0.2 | I11: 0 | J11: 0.05
A12: CAT-047 | B12: Nancy Garcia b (4) | C12: 7 | D12: Administracion | E12: Nancy Garcia | F12: 4. Aumentar clima laboral | G12: 0 | H12: 0.1 | I12: 0.1 | J12: 0.03
A13: CAT-047 | B13: Mario | C13: 7 | D13: Sistemas_Y_Procesos | E13: Mario Murillo | F13: 4. Aumentar clima laboral | G13: 0 | H13: 0.1 | I13: 0.1 | J13: 0.15
A14: CAT-047 | B14: Hoja3 | C14: 5 | F14: 4. Aumentar clima laboral | H14: 0.1 | I14: 0.1 | J14: 0.1
A15: CAT-047 | B15: Hoja3 | C15: 24 | F15: 4. Aumentar clima laboral | J15: 0.1
A16: CAT-047 | B16: Hoja1 | C16: 7 | F16: 4. Aumentar clima laboral | G16: Porcentaje | H16: 0.1 | J16: 0.1
A17: CAT-019 | B17: Nancy Garcia b (4) | C17: 8 | D17: Administracion | E17: Nancy Garcia | F17: 2.1 Reducir gasto administrativo x% | G17: % | H17: 0.1 | I17: 0.32 | J17: 0.03
A18: CAT-019 | B18: Julio - Alejandro | C18: 7 | D18: Administracion | F18: 2.1 Reducir gasto administrativo x% | G18: % | H18: 0.1 | I18: 0.32 | J18: 0.1
A19: CAT-019 | B19: Cecilia | C19: 7 | D19: Administracion | F19: 2.1 Reducir gasto administrativo x% | G19: % | H19: 0.1 | I19: 0.32 | J19: 0.05
A20: CAT-019 | B20: Compras | C20: 7 | D20: Administracion | F20: 2.1 Reducir gasto administrativo x% | G20: % | H20: 0.1 | I20: 0.32 | J20: 0.1
A21: CAT-019 | B21: Tesoreria | C21: 7 | D21: Administracion | F21: 2.1 Reducir gasto administrativo x% | G21: % | H21: 0.1 | I21: 0.32 | J21: 0.1
A22: CAT-041 | B22: Nancy Garcia b (4) | C22: 9 | D22: Administracion | E22: Nancy Garcia | F22: 3.5 Multas ambientales y fiscales. | G22: 0 | H22: 0 | I22: 0 | J22: 0.03
A23: CAT-041 | B23: Julio - Alejandro | C23: 8 | D23: Administracion | F23: 3.5 Multas ambientales y fiscales. | G23: 0 | H23: 0 | I23: 0 | J23: 0.05
A24: CAT-041 | B24: Tesoreria | C24: 8 | D24: Administracion | F24: 3.5 Multas ambientales y fiscales. | G24: 0 | H24: 0 | I24: 0 | J24: 0.05
A25: CAT-041 | B25: Gasolinera | C25: 9 | D25: Gasolinera | E25: Abner Urbina | F25: 3.5 Multas ambientales y fiscales. | G25: 0 | H25: 0 | I25: 0 | J25: 0.05
A26: CAT-041 | B26: Abner U b | C26: 9 | D26: Gasolinera | E26: Abner Urbina | F26: 3.5 Multas ambientales y fiscales. | G26: 0 | H26: 0 | I26: 0 | J26: 0.1
A27: CAT-069 | B27: Nancy Garcia b (4) | C27: 10 | D27: Administracion | E27: Nancy Garcia | F27: 6.1 Aumentar Rotación de inventario. | G27: 0 | H27: 0.05 | I27: 0 | J27: 0.03
A28: CAT-069 | B28: Cecilia | C28: 8 | D28: Administracion | F28: 6.1 Aumentar Rotación de inventario. | G28: 0 | H28: 0.05 | I28: 0 | J28: 0.05
A29: CAT-069 | B29: Compras | C29: 8 | D29: Administracion | F29: 6.1 Aumentar Rotación de inventario. | G29: 0 | H29: 0.05 | I29: 0 | J29: 0.2
A30: CAT-069 | B30: Tesoreria | C30: 9 | D30: Administracion | F30: 6.1 Aumentar Rotación de inventario. | G30: 0 | H30: 0.05 | I30: 0 | J30: 0.05
A31: CAT-076 | B31: Nancy Garcia b (4) | C31: 11 | D31: Administracion | E31: Nancy Garcia | F31: 7.1 Rotación de cuentas por cobrar. | G31: 0 | H31: 0.1 | I31: 0 | J31: 0.03
A32: CAT-076 | B32: Julio - Alejandro | C32: 13 | D32: Administracion | F32: 7.1 Rotación de cuentas por cobrar. | G32: 0 | H32: 0.1 | I32: 0 | J32: 0.1
A33: CAT-076 | B33: Tesoreria | C33: 10 | D33: Administracion | F33: 7.1 Rotación de cuentas por cobrar. | G33: 0 | H33: 0.1 | I33: 0 | J33: 0.15
A34: CAT-077 | B34: Nancy Garcia b (4) | C34: 12 | D34: Administracion | E34: Nancy Garcia | F34: 7.2 95% de clientes activos dentro del periodo de recuperacion | G34: 0 | H34: 0.2 | I34: 0 | J34: 0.03
A35: CAT-034 | B35: Nancy Garcia b (4) | C35: 13 | D35: Administracion | E35: Nancy Garcia | F35: 2.3 Reducir Costo por km cabezales propios. | G35: $ | H35: 0.05 | I35: 0.6 | J35: 0.03
A36: CAT-034 | B36: Nancy Garcia b (4) | C36: 21 | D36: Administracion | E36: Nancy Garcia | F36: 2.3 Reducir Costo por km cabezales propios. | G36: $ | H36: 0.05 | I36: 0.6 | J36: 0.03
A37: CAT-034 | B37: TRANEXPA | C37: 13 | D37: Transporte | F37: 2.3 Reducir Costo por km cabezales propios. | G37: $ | H37: 0.05 | I37: 0.6 | J37: 0.1
A38: CAT-034 | B38: Cecilia | C38: 9 | D38: Administracion | F38: 2.3 Reducir Costo por km cabezales propios. | G38: $ | H38: 0.05 | I38: 0.6 | J38: 0.2
A39: CAT-034 | B39: Compras | C39: 9 | D39: Administracion | F39: 2.3 Reducir Costo por km cabezales propios. | G39: $ | H39: 0.05 | I39: 0.6 | J39: 0.1
A40: CAT-056 | B40: Nancy Garcia b (4) | C40: 14 | D40: Administracion | E40: Nancy Garcia | F40: 5.2 Productividad cabezales Flota Nueva | G40: 0 | H40: 4500 | I40: 4782 | J40: 0.03
...

Sheet Allowed Values
A1: Row Type | B1: Evaluation Type | C1: Scoring Method | D1: Confidence | E1: Catalog Status | F1: Business Review | G1: Category
A2: ATOMIC KPI | B2: GREATER_IS_BETTER | C2: PROPORTIONAL | D2: HIGH | E2: PROPOSED | F2: YES | G2: Commercial Growth
